Workbook

Sheet PesoMatPrima
A1: =CONCATENATE("PESO DE MATERIA PRIMA EN GRAMOS MAS EL ",$B$62," % DE MERMA") -> PESO DE MATERIA PRIMA EN GRAMOS MAS EL 8 % DE MERMA
A2: ITEM | B2: DETALLE | C2: 2 | D2: 4 | E2: 6 | F2: 8 | G2: 10 | H2: 12 | I2: 14 | J2: 16/34 | K2: 36/XS | L2: 38/S | M2: 40/M | N2: 42/L | O2: 44/XL | P2: 46/2XL | Q2: 48/3XL | R2: 50/4XL
A3: 1 | B3: Pantalón de vestir | C3: =IF(C34>0,C34*($B$62/100+1),0) -> 0 | D3: =IF(D34>0,D34*($B$62/100+1),0) -> 0 | E3: =IF(E34>0,E34*($B$62/100+1),0) -> 0 | F3: =IF(F34>0,F34*($B$62/100+1),0) -> 0 | G3: =IF(G34>0,G34*($B$62/100+1),0) -> 0 | H3: =IF(H34>0,H34*($B$62/100+1),0) -> 0 | I3: =IF(I34>0,I34*($B$62/100+1),0) -> 0 | J3: =IF(J34>0,J34*($B$62/100+1),0) -> 340.2 | ... R3: =IF(R34>0,R34*($B$62/100+1),0) -> 464.4
A4: 2 | B4: Camisa manga corta | C4: =IF(C35>0,C35*($B$62/100+1),0) -> 104.76 | D4: =IF(D35>0,D35*($B$62/100+1),0) -> 112.32 | E4: =IF(E35>0,E35*($B$62/100+1),0) -> 119.88 | F4: =IF(F35>0,F35*($B$62/100+1),0) -> 127.44 | G4: =IF(G35>0,G35*($B$62/100+1),0) -> 135 | H4: =IF(H35>0,H35*($B$62/100+1),0) -> 142.56 | I4: =IF(I35>0,I35*($B$62/100+1),0) -> 150.12 | J4: =IF(J35>0,J35*($B$62/100+1),0) -> 157.68 | L4: =IF(L35>0,L35*($B$62/100+1),0) -> 165.24 | M4: =IF(M35>0,M35*($B$62/100+1),0) -> 172.8 | N4: =IF(N35>0,N35*($B$62/100+1),0) -> 180.36 | O4: =IF(O35>0,O35*($B$62/100+1),0) -> 187.92 | P4: =IF(P35>0,P35*($B$62/100+1),0) -> 197.64 | Q4: =IF(Q35>0,Q35*($B$62/100+1),0) -> 206.28
A5: 3 | B5: Camisa manga larga | C5: =IF(C36>0,C36*($B$62/100+1),0) -> 115.56 | D5: =IF(D36>0,D36*($B$62/100+1),0) -> 123.12 | E5: =IF(E36>0,E36*($B$62/100+1),0) -> 130.68 | F5: =IF(F36>0,F36*($B$62/100+1),0) -> 138.24 | G5: =IF(G36>0,G36*($B$62/100+1),0) -> 145.8 | H5: =IF(H36>0,H36*($B$62/100+1),0) -> 153.36 | I5: =IF(I36>0,I36*($B$62/100+1),0) -> 160.92 | J5: =IF(J36>0,J36*($B$62/100+1),0) -> 168.48 | L5: =IF(L36>0,L36*($B$62/100+1),0) -> 176.04 | M5: =IF(M36>0,M36*($B$62/100+1),0) -> 183.6 | N5: =IF(N36>0,N36*($B$62/100+1),0) -> 191.16 | O5: =IF(O36>0,O36*($B$62/100+1),0) -> 198.72 | P5: =IF(P36>0,P36*($B$62/100+1),0) -> 208.44 | Q5: =IF(Q36>0,Q36*($B$62/100+1),0) -> 217.08
A6: 4 | B6: Corbata larga | C6: =IF(C37>0,C37*($B$62/100+1),0) -> 0 | D6: =IF(D37>0,D37*($B$62/100+1),0) -> 0 | E6: =IF(E37>0,E37*($B$62/100+1),0) -> 0 | F6: =IF(F37>0,F37*($B$62/100+1),0) -> 0 | G6: =IF(G37>0,G37*($B$62/100+1),0) -> 0 | H6: =IF(H37>0,H37*($B$62/100+1),0) -> 0 | I6: =IF(I37>0,I37*($B$62/100+1),0) -> 0 | J6: =IF(J37>0,J37*($B$62/100+1),0) -> 0 | ... Q6: =IF(Q37>0,Q37*($B$62/100+1),0) -> 0
A7: 5 | B7: Pantalón con elástico | C7: =IF(C38>0,C38*($B$62/100+1),0) -> 145.8 | D7: =IF(D38>0,D38*($B$62/100+1),0) -> 168.48 | E7: =IF(E38>0,E38*($B$62/100+1),0) -> 191.16 | F7: =IF(F38>0,F38*($B$62/100+1),0) -> 214.92 | G7: =IF(G38>0,G38*($B$62/100+1),0) -> 237.6 | H7: =IF(H38>0,H38*($B$62/100+1),0) -> 257.04 | I7: =IF(I38>0,I38*($B$62/100+1),0) -> 276.48 | J7: =IF(J38>0,J38*($B$62/100+1),0) -> 295.92 | ... Q7: =IF(Q38>0,Q38*($B$62/100+1),0) -> 0
A8: 6 | B8: Bermuda | C8: =IF(C39>0,C39*($B$62/100+1),0) -> 99.36 | D8: =IF(D39>0,D39*($B$62/100+1),0) -> 108 | E8: =IF(E39>0,E39*($B$62/100+1),0) -> 119.88 | F8: =IF(F39>0,F39*($B$62/100+1),0) -> 133.92 | G8: =IF(G39>0,G39*($B$62/100+1),0) -> 153.36 | H8: =IF(H39>0,H39*($B$62/100+1),0) -> 171.72 | I8: =IF(I39>0,I39*($B$62/100+1),0) -> 178.2 | J8: =IF(J39>0,J39*($B$62/100+1),0) -> 192.24 | ... Q8: =IF(Q39>0,Q39*($B$62/100+1),0) -> 0
A9: 7 | B9: Polera manga corta | C9: =IF(C40>0,C40*($B$62/100+1),0) -> 100.44 | D9: =IF(D40>0,D40*($B$62/100+1),0) -> 108 | E9: =IF(E40>0,E40*($B$62/100+1),0) -> 115.56 | F9: =IF(F40>0,F40*($B$62/100+1),0) -> 132.84 | G9: =IF(G40>0,G40*($B$62/100+1),0) -> 150.12 | H9: =IF(H40>0,H40*($B$62/100+1),0) -> 155.52 | I9: =IF(I40>0,I40*($B$62/100+1),0) -> 160.92 | J9: =IF(J40>0,J40*($B$62/100+1),0) -> 168.48 | L9: =IF(L40>0,L40*($B$62/100+1),0) -> 176.04 | M9: =IF(M40>0,M40*($B$62/100+1),0) -> 183.6 | N9: =IF(N40>0,N40*($B$62/100+1),0) -> 191.16 | O9: =IF(O40>0,O40*($B$62/100+1),0) -> 200.88 | P9: =IF(P40>0,P40*($B$62/100+1),0) -> 210.6 | Q9: =IF(Q40>0,Q40*($B$62/100+1),0) -> 231.12
A10: 8 | B10: Polera manga larga | C10: =IF(C41>0,C41*($B$62/100+1),0) -> 116.64 | D10: =IF(D41>0,D41*($B$62/100+1),0) -> 124.2 | E10: =IF(E41>0,E41*($B$62/100+1),0) -> 131.76 | F10: =IF(F41>0,F41*($B$62/100+1),0) -> 149.04 | G10: =IF(G41>0,G41*($B$62/100+1),0) -> 177.12 | H10: =IF(H41>0,H41*($B$62/100+1),0) -> 182.52 | I10: =IF(I41>0,I41*($B$62/100+1),0) -> 187.92 | J10: =IF(J41>0,J41*($B$62/100+1),0) -> 195.48 | L10: =IF(L41>0,L41*($B$62/100+1),0) -> 208.44 | M10: =IF(M41>0,M41*($B$62/100+1),0) -> 216 | N10: =IF(N41>0,N41*($B$62/100+1),0) -> 223.56 | O10: =IF(O41>0,O41*($B$62/100+1),0) -> 233.28 | P10: =IF(P41>0,P41*($B$62/100+1),0) -> 243 | Q10: =IF(Q41>0,Q41*($B$62/100+1),0) -> 263.52
A11: 9 | B11: Short | C11: =IF(C42>0,C42*($B$62/100+1),0) -> 65.88 | D11: =IF(D42>0,D42*($B$62/100+1),0) -> 70.2 | E11: =IF(E42>0,E42*($B$62/100+1),0) -> 74.52 | F11: =IF(F42>0,F42*($B$62/100+1),0) -> 77.76 | G11: =IF(G42>0,G42*($B$62/100+1),0) -> 81 | H11: =IF(H42>0,H42*($B$62/100+1),0) -> 86.4 | I11: =IF(I42>0,I42*($B$62/100+1),0) -> 97.2 | J11: =IF(J42>0,J42*($B$62/100+1),0) -> 105.84 | L11: =IF(L42>0,L42*($B$62/100+1),0) -> 113.4 | M11: =IF(M42>0,M42*($B$62/100+1),0) -> 119.88 | N11: =IF(N42>0,N42*($B$62/100+1),0) -> 126.36 | O11: =IF(O42>0,O42*($B$62/100+1),0) -> 131.76 | P11: =IF(P42>0,P42*($B$62/100+1),0) -> 141.48 | Q11: =IF(Q42>0,Q42*($B$62/100+1),0) -> 150.12
A12: 10 | B12: Calza corta | C12: =IF(C43>0,C43*($B$62/100+1),0) -> 84.24 | D12: =IF(D43>0,D43*($B$62/100+1),0) -> 92.88 | E12: =IF(E43>0,E43*($B$62/100+1),0) -> 101.52 | F12: =IF(F43>0,F43*($B$62/100+1),0) -> 110.16 | G12: =IF(G43>0,G43*($B$62/100+1),0) -> 118.8 | H12: =IF(H43>0,H43*($B$62/100+1),0) -> 127.44 | I12: =IF(I43>0,I43*($B$62/100+1),0) -> 136.08 | J12: =IF(J43>0,J43*($B$62/100+1),0) -> 144.72 | L12: =IF(L43>0,L43*($B$62/100+1),0) -> 153.36 | M12: =IF(M43>0,M43*($B$62/100+1),0) -> 162 | N12: =IF(N43>0,N43*($B$62/100+1),0) -> 172.8 | O12: =IF(O43>0,O43*($B$62/100+1),0) -> 183.6 | P12: =IF(P43>0,P43*($B$62/100+1),0) -> 193.32 | Q12: =IF(Q43>0,Q43*($B$62/100+1),0) -> 205.2
A13: 11 | B13: Calza larga | C13: =IF(C44>0,C44*($B$62/100+1),0) -> 117.72 | D13: =IF(D44>0,D44*($B$62/100+1),0) -> 131.76 | E13: =IF(E44>0,E44*($B$62/100+1),0) -> 145.8 | F13: =IF(F44>0,F44*($B$62/100+1),0) -> 156.6 | G13: =IF(G44>0,G44*($B$62/100+1),0) -> 167.4 | H13: =IF(H44>0,H44*($B$62/100+1),0) -> 246.24 | I13: =IF(I44>0,I44*($B$62/100+1),0) -> 270 | J13: =IF(J44>0,J44*($B$62/100+1),0) -> 282.96 | L13: =IF(L44>0,L44*($B$62/100+1),0) -> 298.08 | M13: =IF(M44>0,M44*($B$62/100+1),0) -> 302.4 | N13: =IF(N44>0,N44*($B$62/100+1),0) -> 305.64 | O13: =IF(O44>0,O44*($B$62/100+1),0) -> 313.2 | P13: =IF(P44>0,P44*($B$62/100+1),0) -> 329.4 | Q13: =IF(Q44>0,Q44*($B$62/100+1),0) -> 343.44
A14: 12 | B14: Pantalón para dama | C14: =IF(C45>0,C45*($B$62/100+1),0) -> 0 | D14: =IF(D45>0,D45*($B$62/100+1),0) -> 0 | E14: =IF(E45>0,E45*($B$62/100+1),0) -> 0 | F14: =IF(F45>0,F45*($B$62/100+1),0) -> 0 | G14: =IF(G45>0,G45*($B$62/100+1),0) -> 0 | H14: =IF(H45>0,H45*($B$62/100+1),0) -> 0 | I14: =IF(I45>0,I45*($B$62/100+1),0) -> 0 | J14: =IF(J45>0,J45*($B$62/100+1),0) -> 249.48 | ... Q14: =IF(Q45>0,Q45*($B$62/100+1),0) -> 340.2
A15: 13 | B15: Blusa manga corta | C15: =IF(C46>0,C46*($B$62/100+1),0) -> 70.2 | D15: =IF(D46>0,D46*($B$62/100+1),0) -> 76.68 | E15: =IF(E46>0,E46*($B$62/100+1),0) -> 82.08 | F15: =IF(F46>0,F46*($B$62/100+1),0) -> 97.2 | G15: =IF(G46>0,G46*($B$62/100+1),0) -> 108 | H15: =IF(H46>0,H46*($B$62/100+1),0) -> 115.56 | I15: =IF(I46>0,I46*($B$62/100+1),0) -> 117.72 | J15: =IF(J46>0,J46*($B$62/100+1),0) -> 123.12 | ... Q15: =IF(Q46>0,Q46*($B$62/100+1),0) -> 156.6
A16: 14 | B16: Blusa manga larga | C16: =IF(C47>0,C47*($B$62/100+1),0) -> 74.52 | D16: =IF(D47>0,D47*($B$62/100+1),0) -> 81 | E16: =IF(E47>0,E47*($B$62/100+1),0) -> 86.4 | F16: =IF(F47>0,F47*($B$62/100+1),0) -> 101.52 | G16: =IF(G47>0,G47*($B$62/100+1),0) -> 113.4 | H16: =IF(H47>0,H47*($B$62/100+1),0) -> 120.96 | I16: =IF(I47>0,I47*($B$62/100+1),0) -> 123.12 | J16: =IF(J47>0,J47*($B$62/100+1),0) -> 128.52 | ... Q16: =IF(Q47>0,Q47*($B$62/100+1),0) -> 164.16
A17: 15 | B17: Corbata con elástico | C17: =IF(C48>0,C48*($B$62/100+1),0) -> 21.6 | D17: =IF(D48>0,D48*($B$62/100+1),0) -> 0 | E17: =IF(E48>0,E48*($B$62/100+1),0) -> 0 | F17: =IF(F48>0,F48*($B$62/100+1),0) -> 0 | G17: =IF(G48>0,G48*($B$62/100+1),0) -> 0 | H17: =IF(H48>0,H48*($B$62/100+1),0) -> 0 | I17: =IF(I48>0,I48*($B$62/100+1),0) -> 0 | J17: =IF(J48>0,J48*($B$62/100+1),0) -> 0 | ... Q17: =IF(Q48>0,Q48*($B$62/100+1),0) -> 0
A18: 16 | B18: Falda plisada | C18: =IF(C49>0,C49*($B$62/100+1),0) -> 140.4 | D18: =IF(D49>0,D49*($B$62/100+1),0) -> 149.04 | E18: =IF(E49>0,E49*($B$62/100+1),0) -> 157.68 | F18: =IF(F49>0,F49*($B$62/100+1),0) -> 166.32 | G18: =IF(G49>0,G49*($B$62/100+1),0) -> 174.96 | H18: =IF(H49>0,H49*($B$62/100+1),0) -> 183.6 | I18: =IF(I49>0,I49*($B$62/100+1),0) -> 193.32 | J18: =IF(J49>0,J49*($B$62/100+1),0) -> 201.96 | L18: =IF(L49>0,L49*($B$62/100+1),0) -> 210.6 | M18: =IF(M49>0,M49*($B$62/100+1),0) -> 219.24 | N18: =IF(N49>0,N49*($B$62/100+1),0) -> 227.88 | O18: =IF(O49>0,O49*($B$62/100+1),0) -> 236.52 | P18: =IF(P49>0,P49*($B$62/100+1),0) -> 245.16 | Q18: =IF(Q49>0,Q49*($B$62/100+1),0) -> 253.8
A19: 17 | B19: Jamper | C19: =IF(C50>0,C50*($B$62/100+1),0) -> 118.8 | D19: =IF(D50>0,D50*($B$62/100+1),0) -> 131.76 | E19: =IF(E50>0,E50*($B$62/100+1),0) -> 144.72 | F19: =IF(F50>0,F50*($B$62/100+1),0) -> 157.68 | G19: =IF(G50>0,G50*($B$62/100+1),0) -> 170.64 | H19: =IF(H50>0,H50*($B$62/100+1),0) -> 183.6 | I19: =IF(I50>0,I50*($B$62/100+1),0) -> 0 | J19: =IF(J50>0,J50*($B$62/100+1),0) -> 0 | ... Q19: =IF(Q50>0,Q50*($B$62/100+1),0) -> 0
A20: 18 | B20: Vestido | C20: =IF(C51>0,C51*($B$62/100+1),0) -> 153.36 | D20: =IF(D51>0,D51*($B$62/100+1),0) -> 173.88 | E20: =IF(E51>0,E51*($B$62/100+1),0) -> 194.4 | F20: =IF(F51>0,F51*($B$62/100+1),0) -> 214.92 | G20: =IF(G51>0,G51*($B$62/100+1),0) -> 235.44 | H20: =IF(H51>0,H51*($B$62/100+1),0) -> 255.96 | I20: =IF(I51>0,I51*($B$62/100+1),0) -> 0 | J20: =IF(J51>0,J51*($B$62/100+1),0) -> 0 | ... Q20: =IF(Q51>0,Q51*($B$62/100+1),0) -> 0
A21: 19 | B21: Chompa cuello en V | C21: =IF(C52>0,C52*($B$62/100+1),0) -> 0 | D21: =IF(D52>0,D52*($B$62/100+1),0) -> 0 | E21: =IF(E52>0,E52*($B$62/100+1),0) -> 0 | F21: =IF(F52>0,F52*($B$62/100+1),0) -> 0 | G21: =IF(G52>0,G52*($B$62/100+1),0) -> 0 | H21: =IF(H52>0,H52*($B$62/100+1),0) -> 0 | I21: =IF(I52>0,I52*($B$62/100+1),0) -> 0 | J21: =IF(J52>0,J52*($B$62/100+1),0) -> 0 | ... Q21: =IF(Q52>0,Q52*($B$62/100+1),0) -> 0
A22: 20 | B22: Chaleco cuello en V | C22: =IF(C53>0,C53*($B$62/100+1),0) -> 0 | D22: =IF(D53>0,D53*($B$62/100+1),0) -> 0 | E22: =IF(E53>0,E53*($B$62/100+1),0) -> 0 | F22: =IF(F53>0,F53*($B$62/100+1),0) -> 0 | G22: =IF(G53>0,G53*($B$62/100+1),0) -> 0 | H22: =IF(H53>0,H53*($B$62/100+1),0) -> 0 | I22: =IF(I53>0,I53*($B$62/100+1),0) -> 0 | J22: =IF(J53>0,J53*($B$62/100+1),0) -> 0 | ... Q22: =IF(Q53>0,Q53*($B$62/100+1),0) -> 0
A23: 21 | B23: Chamarra de verano | C23: =IF(C54>0,C54*($B$62/100+1),0) -> 316.44 | D23: =IF(D54>0,D54*($B$62/100+1),0) -> 328.32 | E23: =IF(E54>0,E54*($B$62/100+1),0) -> 340.2 | F23: =IF(F54>0,F54*($B$62/100+1),0) -> 352.08 | G23: =IF(G54>0,G54*($B$62/100+1),0) -> 363.96 | H23: =IF(H54>0,H54*($B$62/100+1),0) -> 375.84 | I23: =IF(I54>0,I54*($B$62/100+1),0) -> 387.72 | J23: =IF(J54>0,J54*($B$62/100+1),0) -> 399.6 | L23: =IF(L54>0,L54*($B$62/100+1),0) -> 409.32 | M23: =IF(M54>0,M54*($B$62/100+1),0) -> 419.04 | N23: =IF(N54>0,N54*($B$62/100+1),0) -> 430.92 | O23: =IF(O54>0,O54*($B$62/100+1),0) -> 439.56 | P23: =IF(P54>0,P54*($B$62/100+1),0) -> 449.28 | Q23: =IF(Q54>0,Q54*($B$62/100+1),0) -> 460.08
A24: 22 | B24: Chamarra deportiva | C24: =IF(C55>0,C55*($B$62/100+1),0) -> 316.44 | D24: =IF(D55>0,D55*($B$62/100+1),0) -> 328.32 | E24: =IF(E55>0,E55*($B$62/100+1),0) -> 340.2 | F24: =IF(F55>0,F55*($B$62/100+1),0) -> 352.08 | G24: =IF(G55>0,G55*($B$62/100+1),0) -> 363.96 | H24: =IF(H55>0,H55*($B$62/100+1),0) -> 375.84 | I24: =IF(I55>0,I55*($B$62/100+1),0) -> 387.72 | J24: =IF(J55>0,J55*($B$62/100+1),0) -> 399.6 | L24: =IF(L55>0,L55*($B$62/100+1),0) -> 409.32 | M24: =IF(M55>0,M55*($B$62/100+1),0) -> 419.04 | N24: =IF(N55>0,N55*($B$62/100+1),0) -> 430.92 | O24: =IF(O55>0,O55*($B$62/100+1),0) -> 439.56 | P24: =IF(P55>0,P55*($B$62/100+1),0) -> 449.28 | Q24: =IF(Q55>0,Q55*($B$62/100+1),0) -> 460.08
A25: 23 | B25: Chamarra de invierno | C25: =IF(C56>0,C56*($B$62/100+1),0) -> 348.084 | D25: =IF(D56>0,D56*($B$62/100+1),0) -> 361.152 | E25: =IF(E56>0,E56*($B$62/100+1),0) -> 374.22 | F25: =IF(F56>0,F56*($B$62/100+1),0) -> 387.288 | G25: =IF(G56>0,G56*($B$62/100+1),0) -> 400.356 | H25: =IF(H56>0,H56*($B$62/100+1),0) -> 413.424 | I25: =IF(I56>0,I56*($B$62/100+1),0) -> 426.492 | J25: =IF(J56>0,J56*($B$62/100+1),0) -> 439.56 | L25: =IF(L56>0,L56*($B$62/100+1),0) -> 450.252 | M25: =IF(M56>0,M56*($B$62/100+1),0) -> 460.944 | N25: =IF(N56>0,N56*($B$62/100+1),0) -> 474.012 | O25: =IF(O56>0,O56*($B$62/100+1),0) -> 483.516 | P25: =IF(P56>0,P56*($B$62/100+1),0) -> 494.208 | Q25: =IF(Q56>0,Q56*($B$62/100+1),0) -> 506.088
A26: 24 | B26: Buso Deportivo | C26: =IF(C57>0,C57*($B$62/100+1),0) -> 218.16 | D26: =IF(D57>0,D57*($B$62/100+1),0) -> 241.92 | E26: =IF(E57>0,E57*($B$62/100+1),0) -> 265.68 | F26: =IF(F57>0,F57*($B$62/100+1),0) -> 289.44 | G26: =IF(G57>0,G57*($B$62/100+1),0) -> 313.2 | H26: =IF(H57>0,H57*($B$62/100+1),0) -> 336.96 | I26: =IF(I57>0,I57*($B$62/100+1),0) -> 362.88 | J26: =IF(J57>0,J57*($B$62/100+1),0) -> 389.88 | L26: =IF(L57>0,L57*($B$62/100+1),0) -> 410.4 | M26: =IF(M57>0,M57*($B$62/100+1),0) -> 424.44 | N26: =IF(N57>0,N57*($B$62/100+1),0) -> 438.48 | O26: =IF(O57>0,O57*($B$62/100+1),0) -> 452.52 | P26: =IF(P57>0,P57*($B$62/100+1),0) -> 470.88 | Q26: =IF(Q57>0,Q57*($B$62/100+1),0) -> 487.08
A27: 25 | B27: Polera de colores | C27: =IF(C58>0,C58*($B$62/100+1),0) -> 100.44 | D27: =IF(D58>0,D58*($B$62/100+1),0) -> 108 | E27: =IF(E58>0,E58*($B$62/100+1),0) -> 115.56 | F27: =IF(F58>0,F58*($B$62/100+1),0) -> 132.84 | G27: =IF(G58>0,G58*($B$62/100+1),0) -> 150.12 | H27: =IF(H58>0,H58*($B$62/100+1),0) -> 155.52 | I27: =IF(I58>0,I58*($B$62/100+1),0) -> 160.92 | J27: =IF(J58>0,J58*($B$62/100+1),0) -> 168.48 | L27: =IF(L58>0,L58*($B$62/100+1),0) -> 0 | M27: =IF(M58>0,M58*($B$62/100+1),0) -> 0 | N27: =IF(N58>0,N58*($B$62/100+1),0) -> 0 | O27: =IF(O58>0,O58*($B$62/100+1),0) -> 0 | P27: =IF(P58>0,P58*($B$62/100+1),0) -> 0 | Q27: =IF(Q58>0,Q58*($B$62/100+1),0) -> 0
A28: 26 | B28: Polera Bullying | C28: =IF(C59>0,C59*($B$62/100+1),0) -> 129.6 | D28: =IF(D59>0,D59*($B$62/100+1),0) -> 0 | E28: =IF(E59>0,E59*($B$62/100+1),0) -> 0 | F28: =IF(F59>0,F59*($B$62/100+1),0) -> 0 | G28: =IF(G59>0,G59*($B$62/100+1),0) -> 0 | H28: =IF(H59>0,H59*($B$62/100+1),0) -> 0 | I28: =IF(I59>0,I59*($B$62/100+1),0) -> 0 | J28: =IF(J59>0,J59*($B$62/100+1),0) -> 0 | L28: =IF(L59>0,L59*($B$62/100+1),0) -> 0 | M28: =IF(M59>0,M59*($B$62/100+1),0) -> 0 | N28: =IF(N59>0,N59*($B$62/100+1),0) -> 0 | O28: =IF(O59>0,O59*($B$62/100+1),0) -> 0 | P28: =IF(P59>0,P59*($B$62/100+1),0) -> 0 | Q28: =IF(Q59>0,Q59*($B$62/100+1),0) -> 0
A29: 27 | B29: Saco | C29: =IF(C60>0,C60*($B$62/100+1),0) -> 378 | D29: =IF(D60>0,D60*($B$62/100+1),0) -> 405 | E29: =IF(E60>0,E60*($B$62/100+1),0) -> 432 | F29: =IF(F60>0,F60*($B$62/100+1),0) -> 459 | G29: =IF(G60>0,G60*($B$62/100+1),0) -> 486 | H29: =IF(H60>0,H60*($B$62/100+1),0) -> 513 | I29: =IF(I60>0,I60*($B$62/100+1),0) -> 540 | J29: =IF(J60>0,J60*($B$62/100+1),0) -> 567 | L29: =IF(L60>0,L60*($B$62/100+1),0) -> 594 | M29: =IF(M60>0,M60*($B$62/100+1),0) -> 621 | N29: =IF(N60>0,N60*($B$62/100+1),0) -> 648 | O29: =IF(O60>0,O60*($B$62/100+1),0) -> 675 | P29: =IF(P60>0,P60*($B$62/100+1),0) -> 702 | Q29: =IF(Q60>0,Q60*($B$62/100+1),0) -> 729
A32: PESO DE MATERIA PRIMA ESTIMADO EN GRAMOS
A33: ITEM | B33: DETALLE | C33: 2 | D33: 4 | E33: 6 | F33: 8 | G33: 10 | H33: 12 | I33: 14 | J33: 16/34 | K33: 36/XS | L33: 38/S | M33: 40/M | N33: 42/L | O33: 44/XL | P33: 46/2XL | Q33: 48/3XL
A34: 1 | B34: Pantalón de vestir | C34: 0 | D34: 0 | E34: 0 | F34: 0 | G34: 0 | H34: 0 | I34: 0 | J34: 315 | K34: 335 | L34: 345 | M34: 360 | N34: 375 | O34: 385 | P34: 403 | Q34: 414 | R34: 430
A35: 2 | B35: Camisa manga corta | C35: 97 | D35: 104 | E35: 111 | F35: 118 | G35: 125 | H35: 132 | I35: 139 | J35: 146 | L35: 153 | M35: 160 | N35: 167 | O35: 174 | P35: 183 | Q35: 191
A36: 3 | B36: Camisa manga larga | C36: =C35+10 -> 107 | D36: =D35+10 -> 114 | E36: =E35+10 -> 121 | F36: =F35+10 -> 128 | G36: =G35+10 -> 135 | H36: =H35+10 -> 142 | I36: =I35+10 -> 149 | J36: =J35+10 -> 156 | L36: =L35+10 -> 163 | M36: =M35+10 -> 170 | N36: =N35+10 -> 177 | O36: =O35+10 -> 184 | P36: =P35+10 -> 193 | Q36: =Q35+10 -> 201
A37: 4 | B37: Corbata larga | C37: 0 | D37: 0 | E37: 0 | F37: 0 | G37: 0 | H37: 0 | I37: 0 | J37: 0 | K37: 37 | L37: 0 | M37: 0 | N37: 0 | O37: 0 | P37: 0 | Q37: 0
A38: 5 | B38: Pantalón con elástico | C38: 135 | D38: 156 | E38: 177 | F38: 199 | G38: 220 | H38: 238 | I38: 256 | J38: 274 | L38: 290 | M38: 0 | N38: 0 | O38: 0 | P38: 0 | Q38: 0
A39: 6 | B39: Bermuda | C39: =102-10 -> 92 | D39: =112-12 -> 100 | E39: 111 | F39: 124 | G39: =158-16 -> 142 | H39: =175-16 -> 159 | I39: 165 | J39: =194-16 -> 178 | L39: 196 | M39: 0 | N39: 0 | O39: 0 | P39: 0 | Q39: 0
A40: 7 | B40: Polera manga corta | C40: 93 | D40: 100 | E40: 107 | F40: 123 | G40: 139 | H40: 144 | I40: 149 | J40: =I40+7 -> 156 | L40: 163 | M40: 170 | N40: 177 | O40: 186 | P40: 195 | Q40: 214
A41: 8 | B41: Polera manga larga | C41: =C40+15 -> 108 | D41: =D40+15 -> 115 | E41: =E40+15 -> 122 | F41: =F40+15 -> 138 | G41: =G40+25 -> 164 | H41: =H40+25 -> 169 | I41: =I40+25 -> 174 | J41: =J40+25 -> 181 | L41: =L40+30 -> 193 | M41: =M40+30 -> 200 | N41: =N40+30 -> 207 | O41: =O40+30 -> 216 | P41: =P40+30 -> 225 | Q41: =Q40+30 -> 244
A42: 9 | B42: Short | C42: 61 | D42: 65 | E42: 69 | F42: 72 | G42: 75 | H42: 80 | I42: 90 | J42: 98 | L42: 105 | M42: 111 | N42: 117 | O42: 122 | P42: 131 | Q42: 139
...

Sheet Acc
C1: 1 | D1: =C1+1 -> 2 | E1: =D1+1 -> 3 | F1: =E1+1 -> 4 | G1: =F1+1 -> 5 | H1: =G1+1 -> 6 | I1: =H1+1 -> 7 | J1: =I1+1 -> 8 | K1: =J1+1 -> 9 | ... AA1: =Z1+1 -> 25 | AB1: 26 | AC1: 27 | AD1: 28 | AE1: 29 | AF1: 30 | AG1: 31 | AH1: =AG1+1 -> 32 | AI1: 33 | AJ1: 34 | AK1: 35 | AL1: 36 | AM1: 37 | AN1: 38
A2: DETALLE | B2: ITEM | C2: Botamanga (par) | D2: Cuello | E2: Elastico para berm. y pant. | F2: Elastico Short o buzo | G2: Cinta Antideslizante | H2: Botones Pantalon | I2: Boton de 4 huecos para polo | J2: Boton de chamarra | K2: Entretela de chamarra | L2: Entretela de Camisa | M2: Broche | N2: Cierre corto (pantalon) | O2: Cierre Largo (Chamarra) | P2: Forro de chamarra | Q2: Malla para buzo | R2: Bordado escudo | S2: Bordado espalda Chamarra | T2: Hebilla de falda | U2: Cordon de buzo y short | V2: Campana para buso y short | W2: Bolsa de Polipropileno | X2: Etiqueta de Marca | Y2: Etiqueta de Talla | Z2: Etiqueta de cuidados | AA2: Hilo Tex 24 polyester | AB2: Vinilo para shorts | AC2: Vinilo Calzas | AD2: Serigrafia escudo polera | AE2: Serigrafia rectangulo polera, espalda | AF2: Ojal Grande | AG2: Ojal Pequeño | AH2: Serigrafía calza | AI2: Entretela para pantalon | AJ2: Elastico redondo | AK2: Atracado | AL2: Entretela Corbata | AM2: Serigrafia polera colores | AN2: Serigrafia Bullying | AP2: Total De Accesorios
A3: Pantalón de vestir | B3: 1 | G3: =$G$37 -> 0 | L3: =$G$42 -> 1.8 | M3: =$G$43 -> 0.4 | N3: =$G$44 -> 2 | W3: =$G$53 -> 0.22 | X3: =$G$54 -> 1.4 | Y3: =$G$55 -> 0.12 | Z3: =$G$56 -> 0.5 | AA3: =$G$57 -> 0.6 | AI3: =$G$65 -> 0.75 | AK3: =$G$67*3 -> 0.6 | AM3: =$G$69 -> 0 | AN3: =$G$70 -> 0 | AO3: =$G$73 -> 0 | AP3: =SUM(C3:AO3) -> 8.39
A4: Camisa manga corta | B4: =B3+1 -> 2 | I4: =$G$39*7 -> 2.9166667 | L4: =$G$42 -> 1.8 | R4: =$G$48 -> 5 | W4: =$G$53 -> 0.22 | X4: =$G$54 -> 1.4 | Y4: =$G$55 -> 0.12 | Z4: =$G$56 -> 0.5 | AA4: =$G$57 -> 0.6 | AG4: =$G$63*7 -> 2.1 | AM4: =$G$69 -> 0 | AN4: =$G$70 -> 0 | AO4: =$G$73 -> 0 | AP4: =SUM(C4:AO4) -> 14.656667
A5: Camisa manga larga | B5: 3 | I5: =$G$39*9 -> 3.75 | L5: =$G$42 -> 1.8 | R5: =$G$48 -> 5 | W5: =$G$53 -> 0.22 | X5: =$G$54 -> 1.4 | Y5: =$G$55 -> 0.12 | Z5: =$G$56 -> 0.5 | AA5: =$G$57 -> 0.6 | AG5: =$G$63*9 -> 2.7 | AM5: =$G$69 -> 0 | AN5: =$G$70 -> 0 | AO5: =$G$73 -> 0 | AP5: =SUM(C5:AO5) -> 16.09
A6: Corbata larga | B6: 4 | AL6: =$G$68 -> 0.75 | AM6: =$G$69 -> 0 | AN6: =$G$70 -> 0 | AO6: =$G$73 -> 0 | AP6: =SUM(C6:AO6) -> 0.75
A7: Pantalón con elástico | B7: =B6+1 -> 5 | E7: =$G$35 -> 0.36 | M7: =$G$43 -> 0.4 | N7: =$G$44 -> 2 | W7: =$G$53 -> 0.22 | X7: =$G$54 -> 1.4 | Y7: =$G$55 -> 0.12 | Z7: =$G$56 -> 0.5 | AA7: =$G$57 -> 0.6 | AI7: =$G$65/2 -> 0.375 | AK7: =$G$67*10 -> 2 | AM7: =$G$69 -> 0 | AN7: =$G$70 -> 0 | AO7: =$G$73 -> 0 | AP7: =SUM(C7:AO7) -> 7.975
A8: Bermuda | B8: =B7+1 -> 6 | E8: =$G$35 -> 0.36 | M8: =$G$43 -> 0.4 | N8: =$G$44 -> 2 | W8: =$G$53 -> 0.22 | X8: =$G$54 -> 1.4 | Y8: =$G$55 -> 0.12 | Z8: =$G$56 -> 0.5 | AA8: =$G$57 -> 0.6 | AI8: =$G$65 -> 0.75 | AK8: =$G$67*10 -> 2 | AM8: =$G$69 -> 0 | AN8: =$G$70 -> 0 | AO8: =$G$73 -> 0 | AP8: =SUM(C8:AO8) -> 8.35
A9: Polera manga corta/larga | B9: 7-8 | C9: =$G$33 -> 3.5 | D9: =$G$34 -> 2.7 | W9: =$G$53 -> 0.22 | X9: =$G$54 -> 1.4 | Y9: =$G$55 -> 0.12 | Z9: =$G$56 -> 0.5 | AA9: =$G$57 -> 0.6 | AD9: =$G$60 -> 5 | AE9: =$G$61 -> 7 | AM9: =$G$69 -> 0 | AN9: =$G$70 -> 0 | AO9: =$G$73 -> 0 | AP9: =SUM(C9:AO9) -> 21.04
A10: Short | B10: 9 | F10: =$G$36 -> 0.216 | W10: =$G$53 -> 0.22 | X10: =$G$54 -> 1.4 | Y10: =$G$55 -> 0.12 | Z10: =$G$56 -> 0.5 | AA10: =$G$57 -> 0.6 | AB10: =$G$58 -> 4.55 | AM10: =$G$69 -> 0 | AN10: =$G$70 -> 0 | AO10: =$G$73 -> 0 | AP10: =SUM(C10:AO10) -> 7.606
A11: Calza corta/larga | B11: 10-11 | W11: =$G$53 -> 0.22 | X11: =$G$54 -> 1.4 | Y11: =$G$55 -> 0.12 | Z11: =$G$56 -> 0.5 | AA11: =$G$57 -> 0.6 | AC11: =$G$59 -> 3.3 | AM11: =$G$69 -> 0 | AN11: =$G$70 -> 0 | AO11: =$G$73 -> 0 | AP11: =SUM(C11:AO11) -> 6.14
A12: Pantalón para dama | B12: 12 | M12: =$G$43 -> 0.4 | N12: =$G$44 -> 2 | W12: =$G$53 -> 0.22 | X12: =$G$54 -> 1.4 | Y12: =$G$55 -> 0.12 | Z12: =$G$56 -> 0.5 | AA12: =$G$57 -> 0.6 | AI12: =$G$65 -> 0.75 | AK12: =$G$67*10 -> 2 | AM12: =$G$69 -> 0 | AN12: =$G$70 -> 0 | AO12: =$G$73 -> 0 | AP12: =SUM(C12:AO12) -> 7.99
A13: Blusa manga corta | B13: =B12+1 -> 13 | I13: =$G$39*7 -> 2.9166667 | L13: =$G$42 -> 1.8 | R13: =$G$48 -> 5 | W13: =$G$53 -> 0.22 | X13: =$G$54 -> 1.4 | Y13: =$G$55 -> 0.12 | Z13: =$G$56 -> 0.5 | AA13: =$G$57 -> 0.6 | AG13: =$G$63*7 -> 2.1 | AM13: =$G$69 -> 0 | AN13: =$G$70 -> 0 | AO13: =$G$73 -> 0 | AP13: =SUM(C13:AO13) -> 14.656667
A14: Blusa manga larga | B14: =B13+1 -> 14 | I14: =$G$39*7 -> 2.9166667 | L14: =$G$42 -> 1.8 | R14: =$G$48 -> 5 | W14: =$G$53 -> 0.22 | X14: =$G$54 -> 1.4 | Y14: =$G$55 -> 0.12 | Z14: =$G$56 -> 0.5 | AA14: =$G$57 -> 0.6 | AG14: =$G$63*7 -> 2.1 | AM14: =$G$69 -> 0 | AN14: =$G$70 -> 0 | AO14: =$G$73 -> 0 | AP14: =SUM(C14:AO14) -> 14.656667
A15: Corbata con elástico | B15: =B14+1 -> 15 | W15: =$G$53 -> 0.22 | X15: =$G$54 -> 1.4 | Y15: =$G$55 -> 0.12 | Z15: =$G$56 -> 0.5 | AA15: =$G$57 -> 0.6 | AJ15: =$G$66 -> 0.36 | AL15: =$G$68 -> 0.75 | AM15: =$G$69 -> 0 | AN15: =$G$70 -> 0 | AO15: =$G$73 -> 0 | AP15: =SUM(C15:AO15) -> 3.95
A16: Falda plisada | B16: =B15+1 -> 16 | H16: =$G$38*2 -> 0.83333333 | L16: =$G$42 -> 1.8 | T16: =$G$50 -> 5.6 | W16: =$G$53 -> 0.22 | X16: =$G$54 -> 1.4 | Y16: =$G$55 -> 0.12 | Z16: =$G$56 -> 0.5 | AA16: =$G$57 -> 0.6 | AF16: =$G$62*2 -> 1.6 | AM16: =$G$69 -> 0 | AN16: =$G$70 -> 0 | AO16: =$G$73 -> 0 | AP16: =SUM(C16:AO16) -> 12.673333
A17: Jamper | B17: =B16+1 -> 17 | H17: =$G$38*2 -> 0.83333333 | R17: =$G$48 -> 5 | W17: =$G$53 -> 0.22 | X17: =$G$54 -> 1.4 | Y17: =$G$55 -> 0.12 | Z17: =$G$56 -> 0.5 | AA17: =$G$57 -> 0.6 | AF17: =$G$62*2 -> 1.6 | AM17: =$G$69 -> 0 | AN17: =$G$70 -> 0 | AO17: =$G$73 -> 0 | AP17: =SUM(C17:AO17) -> 10.273333
A18: Vestido | B18: =B17+1 -> 18 | H18: =$G$38*2 -> 0.83333333 | R18: =$G$48 -> 5 | W18: =$G$53 -> 0.22 | X18: =$G$54 -> 1.4 | Y18: =$G$55 -> 0.12 | Z18: =$G$56 -> 0.5 | AA18: =$G$57 -> 0.6 | AF18: =$G$62*2 -> 1.6 | AM18: =$G$69 -> 0 | AN18: =$G$70 -> 0 | AO18: =$G$73 -> 0 | AP18: =SUM(C18:AO18) -> 10.273333
A19: Chompa cuello en V | B19: =B18+1 -> 19 | R19: =$G$48 -> 5 | W19: =$G$53 -> 0.22 | X19: =$G$54 -> 1.4 | Y19: =$G$55 -> 0.12 | Z19: =$G$56 -> 0.5 | AA19: =$G$57 -> 0.6 | AM19: =$G$69 -> 0 | AN19: =$G$70 -> 0 | AO19: =$G$73 -> 0 | AP19: =SUM(C19:AO19) -> 7.84
A20: Chaleco cuello en V | B20: =B19+1 -> 20 | R20: =$G$48 -> 5 | W20: =$G$53 -> 0.22 | X20: =$G$54 -> 1.4 | Y20: =$G$55 -> 0.12 | Z20: =$G$56 -> 0.5 | AA20: =$G$57 -> 0.6 | AM20: =$G$69 -> 0 | AN20: =$G$70 -> 0 | AO20: =$G$73 -> 0 | AP20: =SUM(C20:AO20) -> 7.84
A21: Chamarra de verano | B21: =B20+1 -> 21 | J21: =$G$40*3 -> 3.36 | K21: =$G$41 -> 3.6 | O21: =$G$45 -> 2.9166667 | P21: =$G$46 -> 11.25 | R21: =$G$48 -> 5 | S21: =$G$49 -> 7 | U21: =$G$51 -> 1.52 | V21: =$G$52 -> 0.32 | W21: =$G$53 -> 0.22 | X21: =$G$54 -> 1.4 | Y21: =$G$55 -> 0.12 | Z21: =$G$56 -> 0.5 | AA21: =$G$57 -> 0.6 | AM21: =$G$69 -> 0 | AN21: =$G$70 -> 0 | AO21: =$G$73 -> 0 | AP21: =SUM(C21:AO21) -> 37.806667
A22: Chamarra deportiva | B22: =B21+1 -> 22 | J22: =$G$40*3 -> 3.36 | K22: =$G$41 -> 3.6 | O22: =$G$45 -> 2.9166667 | P22: =$G$46 -> 11.25 | R22: =$G$48 -> 5 | S22: =$G$49 -> 7 | U22: =$G$51 -> 1.52 | V22: =$G$52 -> 0.32 | W22: =$G$53 -> 0.22 | X22: =$G$54 -> 1.4 | Y22: =$G$55 -> 0.12 | Z22: =$G$56 -> 0.5 | AA22: =$G$57 -> 0.6 | AM22: =$G$69 -> 0 | AN22: =$G$70 -> 0 | AO22: =$G$73 -> 0 | AP22: =SUM(C22:AO22) -> 37.806667
A23: Chamarra de invierno | B23: =B22+1 -> 23 | J23: =$G$40*3 -> 3.36 | K23: =$G$41 -> 3.6 | O23: =$G$45 -> 2.9166667 | P23: =$G$46 -> 11.25 | R23: =$G$48 -> 5 | S23: =$G$49 -> 7 | U23: =$G$51 -> 1.52 | V23: =$G$52 -> 0.32 | W23: =$G$53 -> 0.22 | X23: =$G$54 -> 1.4 | Y23: =$G$55 -> 0.12 | Z23: =$G$56 -> 0.5 | AA23: =$G$57 -> 0.6 | AM23: =$G$69 -> 0 | AN23: =$G$70 -> 0 | AO23: =$G$73 -> 0 | AP23: =SUM(C23:AO23) -> 37.806667
A24: Buso Deportivo | B24: =B23+1 -> 24 | F24: =$G$36 -> 0.216 | R24: =$G$48 -> 5 | U24: =$G$51 -> 1.52 | V24: =$G$52 -> 0.32 | W24: =$G$53 -> 0.22 | X24: =$G$54 -> 1.4 | Y24: =$G$55 -> 0.12 | Z24: =$G$56 -> 0.5 | AA24: =$G$57 -> 0.6 | AM24: =$G$69 -> 0 | AN24: =$G$70 -> 0 | AO24: =$G$73 -> 0 | AP24: =SUM(C24:AO24) -> 9.896
A25: Polera de colores | B25: =B24+1 -> 25 | C25: =$G$33 -> 3.5 | D25: =$G$34 -> 2.7 | W25: =$G$53 -> 0.22 | X25: =$G$54 -> 1.4 | Y25: =$G$55 -> 0.12 | Z25: =$G$56 -> 0.5 | AA25: =$G$57 -> 0.6 | AM25: =$G$69 -> 0 | AN25: =$G$70 -> 0 | AO25: =$G$73 -> 0 | AP25: =SUM(C25:AO25) -> 9.04
A26: Polera Bullying | B26: =B25+1 -> 26 | C26: =$G$33 -> 3.5 | D26: =$G$34 -> 2.7 | W26: =$G$53 -> 0.22 | X26: =$G$54 -> 1.4 | Y26: =$G$55 -> 0.12 | Z26: =$G$56 -> 0.5 | AA26: =$G$57 -> 0.6 | AM26: =$G$69 -> 0 | AN26: =$G$70 -> 0 | AO26: =$G$73 -> 0 | AP26: =SUM(C26:AO26) -> 9.04
A27: Sacos | B27: =B26+1 -> 27 | H27: =$G$38*2 -> 0.83333333 | K27: =$G$41 -> 3.6 | P27: =$G$46 -> 11.25 | R27: =$G$48 -> 5 | W27: =$G$53 -> 0.22 | X27: =$G$54 -> 1.4 | Y27: =$G$55 -> 0.12 | Z27: =$G$56 -> 0.5 | AA27: =$G$57 -> 0.6 | AM27: =$G$69 -> 0 | AN27: =$G$70 -> 0 | AO27: =$G$73 -> 0 | AP27: =SUM(C27:AO27) -> 23.523333
C28: =$G$33 -> 3.5 | D28: =$G$34 -> 2.7 | E28: =$G$35 -> 0.36 | F28: =$G$36 -> 0.216 | G28: =$G$37 -> 0 | H28: =$G$38 -> 0.41666667 | I28: =$G$39 -> 0.41666667 | J28: =$G$40 -> 1.12 | K28: =$G$41 -> 3.6 | L28: =$G$42 -> 1.8 | M28: =$G$43 -> 0.4 | N28: =$G$44 -> 2 | O28: =$G$45 -> 2.9166667 | P28: =$G$46 -> 11.25 | Q28: =$G$47 -> 0 | R28: =$G$48 -> 5 | S28: =$G$49 -> 7 | T28: =$G$50 -> 5.6 | U28: =$G$51 -> 1.52 | V28: =$G$52 -> 0.32 | W28: =$G$53 -> 0.22 | X28: =$G$54 -> 1.4 | Y28: =$G$55 -> 0.12 | Z28: =$G$56 -> 0.5 | AA28: =$G$57 -> 0.6 | AB28: =$G$58 -> 4.55 | AC28: =$G$59 -> 3.3 | AD28: =$G$60 -> 5 | AE28: =$G$61 -> 7 | AF28: =$G$62 -> 0.8 | AG28: =$G$63 -> 0.3 | AH28: =$G$64 -> 8 | AI28: =$G$65 -> 0.75 | AJ28: =$G$66 -> 0.36 | AK28: =$G$67 -> 0.2 | AL28: =$G$68 -> 0.75 | AM28: =$G$69 -> 0 | AN28: =$G$70 -> 0 | AO28: =$G$73 -> 0 | AP28: =SUM(C28:AO28) -> 83.986
A32: DESCRIPCION | B32: CODIGO | C32: UNIDAD DE COMPRA | D32: Cantidad x "unidad de compra" | E32: COSTO "Unidad de Compra" Bs. | F32: COSTO Unitario Bs. | G32: Costo de Uso en prendas | H32: OJALES | I32: Unidades que se usan por prenda | J32: Unidades por cada metro | K32: Costo por cm2
A33: Botamanga (par) | B33: 1 | C33: PAR | D33: par | F33: 3.5 | G33: 3.5 | I33: 2
A34: Cuello | B34: =B33+1 -> 2 | D34: 1 | F34: 2.7 | G34: 2.7 | I34: 1
A35: Elastico para berm. y pant. | B35: =B34+1 -> 3 | C35: metro | D35: 1 | E35: 0.36 | F35: =E35/D35 -> 0.36 | G35: =Tabla2[[#This Row],[COSTO Unitario Bs.]]*I35 -> 0.36 | I35: 1
A36: Elastico Short o buzo | B36: =B35+1 -> 4 | C36: metro | D36: 1 | E36: 0.36 | F36: =E36/D36 -> 0.36 | G36: 0.216 | I36: 1
A37: Cinta Antideslizante | B37: =B36+1 -> 5 | C37: metro | D37: 1 | E37: 0 | F37: =E37/D37 -> 0 | G37: =Tabla2[[#This Row],[COSTO Unitario Bs.]]*I37 -> 0 | I37: 1
A38: Botones Pantalon | B38: =B37+1 -> 6 | D38: 144 | E38: 60 | F38: =Tabla2[[#This Row],[COSTO "Unidad de Compra" Bs.]]/Tabla2[[#This Row],[Cantidad x "unidad de compra"]] -> 0.41666667 | G38: =Tabla2[[#This Row],[COSTO Unitario Bs.]]*I38 -> 0.41666667 | H38: =3*1 -> 3 | I38: 1
A39: Boton de 4 huecos para polo | B39: =B38+1 -> 7 | C39: Gruesa | D39: 144 | E39: 60 | F39: =E39/D39 -> 0.41666667 | G39: =Tabla2[[#This Row],[COSTO Unitario Bs.]] -> 0.41666667 | H39: =7*1 -> 7 | I39: 7
A40: Boton de chamarra | B40: =B39+1 -> 8 | D40: 1000 | E40: 280 | F40: =E40/D40 -> 0.28 | G40: =F40*I40 -> 1.12 | I40: 4
A41: Entretela de chamarra | B41: =B40+1 -> 9 | C41: metro | D41: 1 | E41: 18 | F41: =E41/D41 -> 18 | G41: =Tabla2[[#This Row],[COSTO Unitario Bs.]]/J41 -> 3.6 | I41: 1 | J41: 5 | K41: 0.0015
A42: Entretela de Camisa | B42: =B41+1 -> 10 | C42: metro | D42: 50 | E42: 900 | F42: =E42/D42 -> 18 | G42: =Tabla2[[#This Row],[COSTO Unitario Bs.]]/J42 -> 1.8 | I42: 1 | J42: 10 | K42: 0.0015
A43: Broche | B43: =B42+1 -> 11 | C43: caja | D43: 200 | E43: 80 | F43: =E43/D43 -> 0.4 | G43: =Tabla2[[#This Row],[COSTO Unitario Bs.]]*I43 -> 0.4 | I43: 1
...

Sheet Tela
A1: Materia Prima
A2: ITEM | B2: Descripción | C2: Rendimiento m / kg | D2: Ancho Extendido/Mts | E2: Unid. | F2: Densidad Gr / mt2 | G2: Peso / mt lineal extendido | H2: Precio unidad de compra/Bs | I2: Precio Bs / Kg | J2: Precio Bs / g | K2: Datos para modificar
A3: 1 | B3: Algodón Nacional, hilo Hindú Poleras | C3: =1000/F3/D3 -> 3.0165913 | D3: 1.7 | E3: kilo | F3: 195 | G3: =F3*D3 -> 331.5 | H3: 97 | I3: =IF($E3="kilo",$H3,(($H3*1000)/$G3)) -> 97 | J3: =I3/1000 -> 0.097
A4: =A3+1 -> 2 | B4: Pique, Nacional Hilo Hindú | C4: =1000/F4/D4 -> 3.003003 | D4: 1.8 | E4: kilo | F4: 185 | G4: =F4*D4 -> 333 | H4: 97 | I4: =IF($E4="kilo",$H4,(($H4*1000)/$G4)) -> 97 | J4: =I4/1000 -> 0.097
A5: =A4+1 -> 3 | B5: Tela Casimir Indú Pantalones | C5: =1000/F5/D5 -> 3.2520325 | D5: 1.5 | E5: metro | F5: 205 | G5: =F5*D5 -> 307.5 | H5: 35 | I5: =IF($E5="kilo",$H5,(($H5*1000)/$G5)) -> 113.82114 | J5: =I5/1000 -> 0.11382114
A6: =A5+1 -> 4 | B6: Popelina Luqui Blusas y camisas | C6: =1000/F6/D6 -> 5.899705 | D6: 1.5 | E6: metro | F6: 113 | G6: =F6*D6 -> 169.5 | H6: 25 | I6: =IF($E6="kilo",$H6,(($H6*1000)/$G6)) -> 147.49263 | J6: =I6/1000 -> 0.14749263 | L6: 1000
A7: =A6+1 -> 5 | B7: Dryfit para shorts | C7: =1000/F7/D7 -> 3.805175 | D7: 1.8 | E7: metro | F7: 146 | G7: =F7*D7 -> 262.8 | H7: 16 | I7: =IF($E7="kilo",$H7,(($H7*1000)/$G7)) -> 60.882801 | J7: =I7/1000 -> 0.060882801 | L7: 182
A8: =A7+1 -> 6 | B8: Licra de algodón para Calzas | C8: =1000/F8/D8 -> 1.9201229 | D8: 1.4 | E8: kilo | F8: 372 | G8: =F8*D8 -> 520.8 | H8: 120 | I8: =IF($E8="kilo",$H8,(($H8*1000)/$G8)) -> 120 | J8: =I8/1000 -> 0.12 | L8: =L7*I6/L6 -> 26.843658
A9: =A8+1 -> 7 | B9: Taslan para chamarras y buzos | C9: =1000/F9/D9 -> 5.7471264 | D9: 1.5 | E9: metro | F9: 116 | G9: =F9*D9 -> 174 | H9: 28 | I9: =IF($E9="kilo",$H9,(($H9*1000)/$G9)) -> 160.91954 | J9: =I9/1000 -> 0.16091954
A10: 8 | B10: Tela Casimir Escoces para faldas/vestidos/corbatas/ | C10: =1000/F10/D10 -> 3.2679739 | D10: 1.5 | E10: metro | F10: 204 | G10: =F10*D10 -> 306 | H10: 60 | I10: =IF($E10="kilo",$H10,(($H10*1000)/$G10)) -> 196.07843 | J10: =I10/1000 -> 0.19607843
A11: 9 | B11: Casimir Italiano para sacos | C11: =1000/F11/D11 -> 1.7362317 | D11: 1.54 | E11: metro | F11: 374 | G11: =F11*D11 -> 575.96 | H11: 70 | I11: =IF($E11="kilo",$H11,(($H11*1000)/$G11)) -> 121.53622 | J11: =I11/1000 -> 0.12153622
A12: 10 | B12: Forro delgado para Chamarras | C12: =1000/F12/D12 -> 9.1324201 | D12: 1.5 | E12: metro | F12: 73 | G12: =F12*D12 -> 109.5 | H12: 7.5 | I12: =IF($E12="kilo",$H12,(($H12*1000)/$G12)) -> 68.493151 | J12: =I12/1000 -> 0.068493151
A13: 11 | B13: Polar | C13: =1000/F13/D13 -> 3.7878788 | D13: 1.5 | E13: metro | F13: 176 | G13: =F13*D13 -> 264 | H13: 18 | I13: =IF($E13="kilo",$H13,(($H13*1000)/$G13)) -> 68.181818 | J13: =I13/1000 -> 0.068181818
A14: 12 | B14: Deportivo para Chamarras y buzos | C14: =1000/F14/D14 -> 2.5641026 | D14: 1.5 | E14: metro | F14: 260 | G14: =F14*D14 -> 390 | H14: 18 | I14: =IF($E14="kilo",$H14,(($H14*1000)/$G14)) -> 46.153846 | J14: =I14/1000 -> 0.046153846

Sheet ManoDeObra
A1: Costo mano de obra | C1: EN BS
A2: ITEM | B2: DETALLE | C2: Tallas 42 -10 | D2: Tallas 12 - S | E2: Tallas M - 4XL
A3: 1 | B3: Pantalón de vestir | C3: 45 | D3: 50 | E3: 55
A4: 2 | B4: Camisa manga corta | C4: 18 | D4: 21 | E4: 25
A5: 3 | B5: Camisa manga larga | C5: 19 | D5: 22 | E5: 26
A6: 4 | B6: Corbata larga | C6: 3.5 | D6: 3.5 | E6: 3.5
A7: 5 | B7: Pantalón con elástico | C7: 18 | D7: 21 | E7: 25
A8: 6 | B8: Bermuda | C8: 18 | D8: 21 | E8: 25
A9: 7 | B9: Polera manga corta | C9: 5 | D9: 5 | E9: 5
A10: 8 | B10: Polera manga larga | C10: 5.5 | D10: 5.5 | E10: 5.5
A11: 9 | B11: Short | C11: 5 | D11: 5 | E11: 5
A12: 10 | B12: Calza corta | C12: 5 | D12: 7 | E12: 9
A13: 11 | B13: Calza larga | C13: 6 | D13: 8 | E13: 10
A14: 12 | B14: Pantalón para dama | C14: 25 | D14: 25 | E14: 25
... A20: 18 | B20: Vestido | C20: 20 | D20: 20 | E20: 20
A21: 19 | B21: Chompa cuello en V
A22: 20 | B22: Chaleco cuello en V
A23: 21 | B23: Chamarra de verano | C23: 25 | D23: 30 | E23: 35
A24: 22 | B24: Chamarra deportiva | C24: 25 | D24: 30 | E24: 35
A25: 23 | B25: Chamarra de invierno | C25: 27 | D25: 32 | E25: 37
A26: 24 | B26: Buso Deportivo | C26: 16 | D26: 18 | E26: 20
A27: 25 | B27: Polera de colores | C27: 5 | D27: 5 | E27: 5
A28: 26 | B28: Polera Bullying | C28: 5 | D28: 5 | E28: 5
A29: 27 | B29: Saco | C29: 100 | D29: 120 | E29: 150

Sheet fijosXprenda
A1: Costos Fijos y variables por prenda
A2: ITEM | B2: DETALLE | C2: Factor de Complejidad | D2: Costo fijo
A3: 1 | B3: Pantalón de vestir | C3: 8 | D3: =('Fij&Var'!$C$16/10)*fijosXprenda!$C3 -> 9.5466667
A4: 2 | B4: Camisa manga corta | C4: 6 | D4: =('Fij&Var'!$C$16/10)*fijosXprenda!$C4 -> 7.16
A5: 3 | B5: Camisa manga larga | C5: 7 | D5: =('Fij&Var'!$C$16/10)*fijosXprenda!$C5 -> 8.3533333
A6: 4 | B6: Corbata larga | C6: 2 | D6: =('Fij&Var'!$C$16/10)*fijosXprenda!$C6 -> 2.3866667
A7: 5 | B7: Pantalón con elástico | C7: 7 | D7: =('Fij&Var'!$C$16/10)*fijosXprenda!$C7 -> 8.3533333
A8: 6 | B8: Bermuda | C8: 6 | D8: =('Fij&Var'!$C$16/10)*fijosXprenda!$C8 -> 7.16
A9: 7 | B9: Polera manga corta | C9: 4 | D9: =('Fij&Var'!$C$16/10)*fijosXprenda!$C9 -> 4.7733333
A10: 8 | B10: Polera manga larga | C10: 4.5 | D10: =('Fij&Var'!$C$16/10)*fijosXprenda!$C10 -> 5.37
A11: 9 | B11: Short | C11: 4 | D11: =('Fij&Var'!$C$16/10)*fijosXprenda!$C11 -> 4.7733333
A12: 10 | B12: Calza corta | C12: 4 | D12: =('Fij&Var'!$C$16/10)*fijosXprenda!$C12 -> 4.7733333
A13: 11 | B13: Calza larga | C13: 4.5 | D13: =('Fij&Var'!$C$16/10)*fijosXprenda!$C13 -> 5.37
A14: 12 | B14: Pantalón para dama | C14: 7 | D14: =('Fij&Var'!$C$16/10)*fijosXprenda!$C14 -> 8.3533333
... A29: 27 | B29: Saco | C29: 10 | D29: =('Fij&Var'!$C$16/10)*fijosXprenda!$C29 -> 11.933333

Sheet Fij&Var
A1: ITEM | B1: Costos indirectos de producción | C1: Costo Mensual
A2: 1 | B2: Costos Personal de Corte | C2: 4000
A3: =A2+1 -> 2 | B3: Costos personal administrativo. | C3: 5500
A4: =A3+1 -> 3 | B4: Costos personal de limpieza, planchado y terminado. | C4: 4500
A5: =A4+1 -> 4 | B5: Mantenimiento y lubricación de maquinaria | C5: 350
A6: =A5+1 -> 5 | B6: Servicio de Electricidad | C6: 1600
A7: =A6+1 -> 6 | B7: Servicio de Agua potable | C7: 250
A8: =A7+1 -> 7 | B8: Servicio de Internet | C8: 280
A9: =A8+1 -> 8 | B9: Hipoteca | C9: 5000
A10: =A9+1 -> 9
A11: =A10+1 -> 10
A12: =A11+1 -> 11
A13: =A12+1 -> 12
B14: Total Costos Indirectos Mensuales | C14: =SUM(C2:C13) -> 21480
B15: Prendas producidas al Mes | C15: 1800
B16: Costo Indirecto por prenda | C16: =C14/C15 -> 11.933333

Sheet Semit.
A1: Costo de Fabricacion semiterminado
A2: ITEM | B2: DETALLE | C2: 2 | D2: 4 | E2: 6 | F2: 8 | G2: 10 | H2: 12 | I2: 14 | J2: 16/34 | K2: 36/XS | L2: 38/S | M2: 40/M | N2: 42/L | O2: 44/XL | P2: 46/2XL | Q2: 48/3XL
A3: 19 | B3: Chompa cuello en V | C3: 50 | D3: 50 | E3: 55 | F3: 60 | G3: 65 | H3: 70 | I3: 75 | J3: 80 | L3: 90 | M3: 100 | N3: 110 | O3: 120 | P3: 130 | Q3: 140
A4: 20 | B4: Chaleco cuello en V | C4: 45 | D4: 45 | E4: 50 | F4: 55 | G4: 60 | H4: 65 | I4: 70 | J4: 75 | L4: 85 | M4: 95 | N4: 105 | O4: 115 | P4: 125 | Q4: 135
B7: Costos anteriores | C7: 47 | D7: 47 | E7: 49 | F7: 52 | G7: 55 | H7: 57 | I7: 62 | J7: 62 | K7: ● | L7: 67 | M7: 67 | N7: 72 | O7: 72 | P7: ● | Q7: ●
C8: 37 | D8: 37 | E8: 39 | F8: 42 | G8: 45 | H8: 47 | I8: 52 | J8: 52 | K8: ● | L8: 57 | M8: 57 | N8: 62 | O8: 62 | P8: ● | Q8: ●

Sheet CostoBruto
A1: COSTO BRUTO | C1: Tela + Accesorios + Mano de obra (SIN FIJOS NI VARIABLES)
A2: ITEM | B2: DETALLE | C2: 2 | D2: 4 | E2: 6 | F2: 8 | G2: 10 | H2: 12 | I2: 14 | J2: 16/34 | K2: 36/XS | L2: 38/S | M2: 40/M | N2: 42/L | O2: 44/XL | P2: 46/2XL | Q2: 48/3XL | R2: 50/4XL
A3: 1 | B3: Pantalón de vestir | C3: =IF(PesoMatPrima!C3>0,(PesoMatPrima!C3*Tela!$J$5)+Acc!$AP$3+ManoDeObra!$C$3,0) -> 0 | D3: =IF(PesoMatPrima!D3>0,(PesoMatPrima!D3*Tela!$J$5)+Acc!$AP$3+ManoDeObra!$C$3,0) -> 0 | E3: =IF(PesoMatPrima!E3>0,(PesoMatPrima!E3*Tela!$J$5)+Acc!$AP$3+ManoDeObra!$C$3,0) -> 0 | F3: =IF(PesoMatPrima!F3>0,(PesoMatPrima!F3*Tela!$J$5)+Acc!$AP$3+ManoDeObra!$C$3,0) -> 0 | G3: =IF(PesoMatPrima!G3>0,(PesoMatPrima!G3*Tela!$J$5)+Acc!$AP$3+ManoDeObra!$C$3,0) -> 0 | H3: =IF(PesoMatPrima!H3>0,(PesoMatPrima!H3*Tela!$J$5)+Acc!$AP$3+ManoDeObra!$D$3,0) -> 0 | I3: =IF(PesoMatPrima!I3>0,(PesoMatPrima!I3*Tela!$J$5)+Acc!$AP$3+ManoDeObra!$D$3,0) -> 0 | J3: =IF(PesoMatPrima!J3>0,(PesoMatPrima!J3*Tela!$J$5)+Acc!$AP$3+ManoDeObra!$D$3,0) -> 97.111951 | K3: =IF(PesoMatPrima!K3>0,(PesoMatPrima!K3*Tela!$J$5)+Acc!$AP$3+ManoDeObra!$D$3,0) -> 99.570488 | L3: =IF(PesoMatPrima!L3>0,(PesoMatPrima!L3*Tela!$J$5)+Acc!$AP$3+ManoDeObra!$E$3,0) -> 105.79976 | M3: =IF(PesoMatPrima!M3>0,(PesoMatPrima!M3*Tela!$J$5)+Acc!$AP$3+ManoDeObra!$E$3,0) -> 107.64366 | N3: =IF(PesoMatPrima!N3>0,(PesoMatPrima!N3*Tela!$J$5)+Acc!$AP$3+ManoDeObra!$E$3,0) -> 109.48756 | O3: =IF(PesoMatPrima!O3>0,(PesoMatPrima!O3*Tela!$J$5)+Acc!$AP$3+ManoDeObra!$E$3,0) -> 110.71683 | P3: =IF(PesoMatPrima!P3>0,(PesoMatPrima!P3*Tela!$J$5)+Acc!$AP$3+ManoDeObra!$E$3,0) -> 112.92951 | Q3: =IF(PesoMatPrima!Q3>0,(PesoMatPrima!Q3*Tela!$J$5)+Acc!$AP$3+ManoDeObra!$E$3,0) -> 114.28171 | R3: =IF(PesoMatPrima!R3>0,(PesoMatPrima!R3*Tela!$J$5)+Acc!$AP$3+ManoDeObra!$E$3,0) -> 116.24854
A4: 2 | B4: Camisa manga corta | C4: =IF(PesoMatPrima!C4>0,(PesoMatPrima!C4*Tela!$J$6)+Acc!$AP$4+ManoDeObra!$C$4,0) -> 48.107994 | D4: =IF(PesoMatPrima!D4>0,(PesoMatPrima!D4*Tela!$J$6)+Acc!$AP$4+ManoDeObra!$C$4,0) -> 49.223038 | E4: =IF(PesoMatPrima!E4>0,(PesoMatPrima!E4*Tela!$J$6)+Acc!$AP$4+ManoDeObra!$C$4,0) -> 50.338083 | F4: =IF(PesoMatPrima!F4>0,(PesoMatPrima!F4*Tela!$J$6)+Acc!$AP$4+ManoDeObra!$C$4,0) -> 51.453127 | G4: =IF(PesoMatPrima!G4>0,(PesoMatPrima!G4*Tela!$J$6)+Acc!$AP$4+ManoDeObra!$C$4,0) -> 52.568171 | H4: =IF(PesoMatPrima!H4>0,(PesoMatPrima!H4*Tela!$J$6)+Acc!$AP$4+ManoDeObra!$D$4,0) -> 56.683215 | I4: =IF(PesoMatPrima!I4>0,(PesoMatPrima!I4*Tela!$J$6)+Acc!$AP$4+ManoDeObra!$D$4,0) -> 57.79826 | J4: =IF(PesoMatPrima!J4>0,(PesoMatPrima!J4*Tela!$J$6)+Acc!$AP$4+ManoDeObra!$D$4,0) -> 58.913304 | K4: =IF(PesoMatPrima!K4>0,(PesoMatPrima!K4*Tela!$J$6)+Acc!$AP$4+ManoDeObra!$D$4,0) -> 0 | L4: =IF(PesoMatPrima!L4>0,(PesoMatPrima!L4*Tela!$J$6)+Acc!$AP$4+ManoDeObra!$D$4,0) -> 60.028348 | M4: =IF(PesoMatPrima!M4>0,(PesoMatPrima!M4*Tela!$J$6)+Acc!$AP$4+ManoDeObra!$E$4,0) -> 65.143392 | N4: =IF(PesoMatPrima!N4>0,(PesoMatPrima!N4*Tela!$J$6)+Acc!$AP$4+ManoDeObra!$E$4,0) -> 66.258437 | O4: =IF(PesoMatPrima!O4>0,(PesoMatPrima!O4*Tela!$J$6)+Acc!$AP$4+ManoDeObra!$E$4,0) -> 67.373481 | P4: =IF(PesoMatPrima!P4>0,(PesoMatPrima!P4*Tela!$J$6)+Acc!$AP$4+ManoDeObra!$E$4,0) -> 68.807109 | Q4: =IF(PesoMatPrima!Q4>0,(PesoMatPrima!Q4*Tela!$J$6)+Acc!$AP$4+ManoDeObra!$E$4,0) -> 70.081445
A5: 3 | B5: Camisa manga larga | C5: =IF(PesoMatPrima!C5>0,(PesoMatPrima!C5*Tela!$J$6)+Acc!$AP$5+ManoDeObra!$C$5,0) -> 52.134248 | D5: =IF(PesoMatPrima!D5>0,(PesoMatPrima!D5*Tela!$J$6)+Acc!$AP$5+ManoDeObra!$C$5,0) -> 53.249292 | E5: =IF(PesoMatPrima!E5>0,(PesoMatPrima!E5*Tela!$J$6)+Acc!$AP$5+ManoDeObra!$C$5,0) -> 54.364336 | F5: =IF(PesoMatPrima!F5>0,(PesoMatPrima!F5*Tela!$J$6)+Acc!$AP$5+ManoDeObra!$C$5,0) -> 55.479381 | G5: =IF(PesoMatPrima!G5>0,(PesoMatPrima!G5*Tela!$J$6)+Acc!$AP$5+ManoDeObra!$C$5,0) -> 56.594425 | H5: =IF(PesoMatPrima!H5>0,(PesoMatPrima!H5*Tela!$J$6)+Acc!$AP$5+ManoDeObra!$D$5,0) -> 60.709469 | I5: =IF(PesoMatPrima!I5>0,(PesoMatPrima!I5*Tela!$J$6)+Acc!$AP$5+ManoDeObra!$D$5,0) -> 61.824513 | J5: =IF(PesoMatPrima!J5>0,(PesoMatPrima!J5*Tela!$J$6)+Acc!$AP$5+ManoDeObra!$D$5,0) -> 62.939558 | K5: =IF(PesoMatPrima!K5>0,(PesoMatPrima!K5*Tela!$J$6)+Acc!$AP$5+ManoDeObra!$D$5,0) -> 0 | L5: =IF(PesoMatPrima!L5>0,(PesoMatPrima!L5*Tela!$J$6)+Acc!$AP$5+ManoDeObra!$D$5,0) -> 64.054602 | M5: =IF(PesoMatPrima!M5>0,(PesoMatPrima!M5*Tela!$J$6)+Acc!$AP$5+ManoDeObra!$E$5,0) -> 69.169646 | N5: =IF(PesoMatPrima!N5>0,(PesoMatPrima!N5*Tela!$J$6)+Acc!$AP$5+ManoDeObra!$E$5,0) -> 70.28469 | O5: =IF(PesoMatPrima!O5>0,(PesoMatPrima!O5*Tela!$J$6)+Acc!$AP$5+ManoDeObra!$E$5,0) -> 71.399735 | P5: =IF(PesoMatPrima!P5>0,(PesoMatPrima!P5*Tela!$J$6)+Acc!$AP$5+ManoDeObra!$E$5,0) -> 72.833363 | Q5: =IF(PesoMatPrima!Q5>0,(PesoMatPrima!Q5*Tela!$J$6)+Acc!$AP$5+ManoDeObra!$E$5,0) -> 74.107699
A6: 4 | B6: Corbata larga | C6: =IF(PesoMatPrima!C6>0,(PesoMatPrima!C6*Tela!$J$10)+Acc!$AP$6+ManoDeObra!$C$6,0) -> 0 | D6: =IF(PesoMatPrima!D6>0,(PesoMatPrima!D6*Tela!$J$10)+Acc!$AP$6+ManoDeObra!$C$6,0) -> 0 | E6: =IF(PesoMatPrima!E6>0,(PesoMatPrima!E6*Tela!$J$10)+Acc!$AP$6+ManoDeObra!$C$6,0) -> 0 | F6: =IF(PesoMatPrima!F6>0,(PesoMatPrima!F6*Tela!$J$10)+Acc!$AP$6+ManoDeObra!$C$6,0) -> 0 | G6: =IF(PesoMatPrima!G6>0,(PesoMatPrima!G6*Tela!$J$10)+Acc!$AP$6+ManoDeObra!$C$6,0) -> 0 | H6: =IF(PesoMatPrima!H6>0,(PesoMatPrima!H6*Tela!$J$10)+Acc!$AP$6+ManoDeObra!$C$6,0) -> 0 | I6: =IF(PesoMatPrima!I6>0,(PesoMatPrima!I6*Tela!$J$10)+Acc!$AP$6+ManoDeObra!$C$6,0) -> 0 | J6: =IF(PesoMatPrima!J6>0,(PesoMatPrima!J6*Tela!$J$10)+Acc!$AP$6+ManoDeObra!$C$6,0) -> 0 | ... Q6: =IF(PesoMatPrima!Q6>0,(PesoMatPrima!Q6*Tela!$J$10)+Acc!$AP$6+ManoDeObra!$C$6,0) -> 0
A7: 5 | B7: Pantalón con elástico | C7: =IF(PesoMatPrima!C7>0,(PesoMatPrima!C7*Tela!$J$5)+Acc!$AP$7+ManoDeObra!$C$7,0) -> 42.570122 | D7: =IF(PesoMatPrima!D7>0,(PesoMatPrima!D7*Tela!$J$5)+Acc!$AP$7+ManoDeObra!$C$7,0) -> 45.151585 | E7: =IF(PesoMatPrima!E7>0,(PesoMatPrima!E7*Tela!$J$5)+Acc!$AP$7+ManoDeObra!$C$7,0) -> 47.733049 | F7: =IF(PesoMatPrima!F7>0,(PesoMatPrima!F7*Tela!$J$5)+Acc!$AP$7+ManoDeObra!$C$7,0) -> 50.437439 | G7: =IF(PesoMatPrima!G7>0,(PesoMatPrima!G7*Tela!$J$5)+Acc!$AP$7+ManoDeObra!$C$7,0) -> 53.018902 | H7: =IF(PesoMatPrima!H7>0,(PesoMatPrima!H7*Tela!$J$5)+Acc!$AP$7+ManoDeObra!$D$7,0) -> 58.231585 | I7: =IF(PesoMatPrima!I7>0,(PesoMatPrima!I7*Tela!$J$5)+Acc!$AP$7+ManoDeObra!$D$7,0) -> 60.444268 | J7: =IF(PesoMatPrima!J7>0,(PesoMatPrima!J7*Tela!$J$5)+Acc!$AP$7+ManoDeObra!$D$7,0) -> 62.656951 | K7: =IF(PesoMatPrima!K7>0,(PesoMatPrima!K7*Tela!$J$5)+Acc!$AP$7+ManoDeObra!$D$7,0) -> 0 | L7: =IF(PesoMatPrima!L7>0,(PesoMatPrima!L7*Tela!$J$5)+Acc!$AP$7+ManoDeObra!$E$7,0) -> 68.62378 | M7: =IF(PesoMatPrima!M7>0,(PesoMatPrima!M7*Tela!$J$5)+Acc!$AP$7+ManoDeObra!$E$7,0) -> 0 | N7: =IF(PesoMatPrima!N7>0,(PesoMatPrima!N7*Tela!$J$5)+Acc!$AP$7+ManoDeObra!$E$7,0) -> 0 | O7: =IF(PesoMatPrima!O7>0,(PesoMatPrima!O7*Tela!$J$5)+Acc!$AP$7+ManoDeObra!$E$7,0) -> 0 | P7: =IF(PesoMatPrima!P7>0,(PesoMatPrima!P7*Tela!$J$5)+Acc!$AP$7+ManoDeObra!$E$7,0) -> 0 | Q7: =IF(PesoMatPrima!Q7>0,(PesoMatPrima!Q7*Tela!$J$5)+Acc!$AP$7+ManoDeObra!$E$7,0) -> 0
A8: 6 | B8: Bermuda | C8: =IF(PesoMatPrima!C8>0,(PesoMatPrima!C8*Tela!$J$5)+Acc!$AP$8+ManoDeObra!$C$8,0) -> 37.659268 | D8: =IF(PesoMatPrima!D8>0,(PesoMatPrima!D8*Tela!$J$5)+Acc!$AP$8+ManoDeObra!$C$8,0) -> 38.642683 | E8: =IF(PesoMatPrima!E8>0,(PesoMatPrima!E8*Tela!$J$5)+Acc!$AP$8+ManoDeObra!$C$8,0) -> 39.994878 | F8: =IF(PesoMatPrima!F8>0,(PesoMatPrima!F8*Tela!$J$5)+Acc!$AP$8+ManoDeObra!$C$8,0) -> 41.592927 | G8: =IF(PesoMatPrima!G8>0,(PesoMatPrima!G8*Tela!$J$5)+Acc!$AP$8+ManoDeObra!$C$8,0) -> 43.80561 | H8: =IF(PesoMatPrima!H8>0,(PesoMatPrima!H8*Tela!$J$5)+Acc!$AP$8+ManoDeObra!$D$8,0) -> 48.895366 | I8: =IF(PesoMatPrima!I8>0,(PesoMatPrima!I8*Tela!$J$5)+Acc!$AP$8+ManoDeObra!$D$8,0) -> 49.632927 | J8: =IF(PesoMatPrima!J8>0,(PesoMatPrima!J8*Tela!$J$5)+Acc!$AP$8+ManoDeObra!$D$8,0) -> 51.230976 | K8: =IF(PesoMatPrima!K8>0,(PesoMatPrima!K8*Tela!$J$5)+Acc!$AP$8+ManoDeObra!$D$8,0) -> 0 | L8: =IF(PesoMatPrima!L8>0,(PesoMatPrima!L8*Tela!$J$5)+Acc!$AP$8+ManoDeObra!$E$8,0) -> 57.443659 | M8: =IF(PesoMatPrima!M8>0,(PesoMatPrima!M8*Tela!$J$5)+Acc!$AP$8+ManoDeObra!$C$8,0) -> 0 | N8: =IF(PesoMatPrima!N8>0,(PesoMatPrima!N8*Tela!$J$5)+Acc!$AP$8+ManoDeObra!$C$8,0) -> 0 | O8: =IF(PesoMatPrima!O8>0,(PesoMatPrima!O8*Tela!$J$5)+Acc!$AP$8+ManoDeObra!$C$8,0) -> 0 | P8: =IF(PesoMatPrima!P8>0,(PesoMatPrima!P8*Tela!$J$5)+Acc!$AP$8+ManoDeObra!$C$8,0) -> 0 | Q8: =IF(PesoMatPrima!Q8>0,(PesoMatPrima!Q8*Tela!$J$5)+Acc!$AP$8+ManoDeObra!$C$8,0) -> 0
A9: 7 | B9: Polera manga corta | C9: =IF(PesoMatPrima!C9>0,(PesoMatPrima!C9*Tela!$J$3)+Acc!$AP$9+ManoDeObra!$C$9,0) -> 35.78268 | D9: =IF(PesoMatPrima!D9>0,(PesoMatPrima!D9*Tela!$J$3)+Acc!$AP$9+ManoDeObra!$C$9,0) -> 36.516 | E9: =IF(PesoMatPrima!E9>0,(PesoMatPrima!E9*Tela!$J$3)+Acc!$AP$9+ManoDeObra!$C$9,0) -> 37.24932 | F9: =IF(PesoMatPrima!F9>0,(PesoMatPrima!F9*Tela!$J$3)+Acc!$AP$9+ManoDeObra!$C$9,0) -> 38.92548 | G9: =IF(PesoMatPrima!G9>0,(PesoMatPrima!G9*Tela!$J$3)+Acc!$AP$9+ManoDeObra!$C$9,0) -> 40.60164 | H9: =IF(PesoMatPrima!H9>0,(PesoMatPrima!H9*Tela!$J$3)+Acc!$AP$9+ManoDeObra!$D$9,0) -> 41.12544 | I9: =IF(PesoMatPrima!I9>0,(PesoMatPrima!I9*Tela!$J$3)+Acc!$AP$9+ManoDeObra!$D$9,0) -> 41.64924 | J9: =IF(PesoMatPrima!J9>0,(PesoMatPrima!J9*Tela!$J$3)+Acc!$AP$9+ManoDeObra!$D$9,0) -> 42.38256 | K9: =IF(PesoMatPrima!K9>0,(PesoMatPrima!K9*Tela!$J$3)+Acc!$AP$9+ManoDeObra!$D$9,0) -> 0 | L9: =IF(PesoMatPrima!L9>0,(PesoMatPrima!L9*Tela!$J$3)+Acc!$AP$9+ManoDeObra!$D$9,0) -> 43.11588 | M9: =IF(PesoMatPrima!M9>0,(PesoMatPrima!M9*Tela!$J$3)+Acc!$AP$9+ManoDeObra!$E$9,0) -> 43.8492 | N9: =IF(PesoMatPrima!N9>0,(PesoMatPrima!N9*Tela!$J$3)+Acc!$AP$9+ManoDeObra!$E$9,0) -> 44.58252 | O9: =IF(PesoMatPrima!O9>0,(PesoMatPrima!O9*Tela!$J$3)+Acc!$AP$9+ManoDeObra!$E$9,0) -> 45.52536 | P9: =IF(PesoMatPrima!P9>0,(PesoMatPrima!P9*Tela!$J$3)+Acc!$AP$9+ManoDeObra!$E$9,0) -> 46.4682 | Q9: =IF(PesoMatPrima!Q9>0,(PesoMatPrima!Q9*Tela!$J$3)+Acc!$AP$9+ManoDeObra!$E$9,0) -> 48.45864
A10: 8 | B10: Polera manga larga | C10: =IF(PesoMatPrima!C10>0,(PesoMatPrima!C10*Tela!$J$3)+Acc!$AP$9+ManoDeObra!$C$10,0) -> 37.85408 | D10: =IF(PesoMatPrima!D10>0,(PesoMatPrima!D10*Tela!$J$3)+Acc!$AP$9+ManoDeObra!$C$10,0) -> 38.5874 | E10: =IF(PesoMatPrima!E10>0,(PesoMatPrima!E10*Tela!$J$3)+Acc!$AP$9+ManoDeObra!$C$10,0) -> 39.32072 | F10: =IF(PesoMatPrima!F10>0,(PesoMatPrima!F10*Tela!$J$3)+Acc!$AP$9+ManoDeObra!$C$10,0) -> 40.99688 | G10: =IF(PesoMatPrima!G10>0,(PesoMatPrima!G10*Tela!$J$3)+Acc!$AP$9+ManoDeObra!$C$10,0) -> 43.72064 | H10: =IF(PesoMatPrima!H10>0,(PesoMatPrima!H10*Tela!$J$3)+Acc!$AP$9+ManoDeObra!$D$10,0) -> 44.24444 | I10: =IF(PesoMatPrima!I10>0,(PesoMatPrima!I10*Tela!$J$3)+Acc!$AP$9+ManoDeObra!$D$10,0) -> 44.76824 | J10: =IF(PesoMatPrima!J10>0,(PesoMatPrima!J10*Tela!$J$3)+Acc!$AP$9+ManoDeObra!$D$10,0) -> 45.50156 | K10: =IF(PesoMatPrima!K10>0,(PesoMatPrima!K10*Tela!$J$3)+Acc!$AP$9+ManoDeObra!$D$10,0) -> 0 | L10: =IF(PesoMatPrima!L10>0,(PesoMatPrima!L10*Tela!$J$3)+Acc!$AP$9+ManoDeObra!$D$10,0) -> 46.75868 | M10: =IF(PesoMatPrima!M10>0,(PesoMatPrima!M10*Tela!$J$3)+Acc!$AP$9+ManoDeObra!$E$10,0) -> 47.492 | N10: =IF(PesoMatPrima!N10>0,(PesoMatPrima!N10*Tela!$J$3)+Acc!$AP$9+ManoDeObra!$E$10,0) -> 48.22532 | O10: =IF(PesoMatPrima!O10>0,(PesoMatPrima!O10*Tela!$J$3)+Acc!$AP$9+ManoDeObra!$E$10,0) -> 49.16816 | P10: =IF(PesoMatPrima!P10>0,(PesoMatPrima!P10*Tela!$J$3)+Acc!$AP$9+ManoDeObra!$E$10,0) -> 50.111 | Q10: =IF(PesoMatPrima!Q10>0,(PesoMatPrima!Q10*Tela!$J$3)+Acc!$AP$9+ManoDeObra!$E$10,0) -> 52.10144
A11: 9 | B11: Short | C11: =IF(PesoMatPrima!C11>0,(PesoMatPrima!C11*Tela!$J$7)+Acc!$AP$10+ManoDeObra!$C$11,0) -> 16.616959 | D11: =IF(PesoMatPrima!D11>0,(PesoMatPrima!D11*Tela!$J$7)+Acc!$AP$10+ManoDeObra!$C$11,0) -> 16.879973 | E11: =IF(PesoMatPrima!E11>0,(PesoMatPrima!E11*Tela!$J$7)+Acc!$AP$10+ManoDeObra!$C$11,0) -> 17.142986 | F11: =IF(PesoMatPrima!F11>0,(PesoMatPrima!F11*Tela!$J$7)+Acc!$AP$10+ManoDeObra!$C$11,0) -> 17.340247 | G11: =IF(PesoMatPrima!G11>0,(PesoMatPrima!G11*Tela!$J$7)+Acc!$AP$10+ManoDeObra!$C$11,0) -> 17.537507 | H11: =IF(PesoMatPrima!H11>0,(PesoMatPrima!H11*Tela!$J$7)+Acc!$AP$10+ManoDeObra!$D$11,0) -> 17.866274 | I11: =IF(PesoMatPrima!I11>0,(PesoMatPrima!I11*Tela!$J$7)+Acc!$AP$10+ManoDeObra!$D$11,0) -> 18.523808 | J11: =IF(PesoMatPrima!J11>0,(PesoMatPrima!J11*Tela!$J$7)+Acc!$AP$10+ManoDeObra!$D$11,0) -> 19.049836 | K11: =IF(PesoMatPrima!K11>0,(PesoMatPrima!K11*Tela!$J$7)+Acc!$AP$10+ManoDeObra!$D$11,0) -> 0 | L11: =IF(PesoMatPrima!L11>0,(PesoMatPrima!L11*Tela!$J$7)+Acc!$AP$10+ManoDeObra!$D$11,0) -> 19.51011 | M11: =IF(PesoMatPrima!M11>0,(PesoMatPrima!M11*Tela!$J$7)+Acc!$AP$10+ManoDeObra!$E$11,0) -> 19.90463 | N11: =IF(PesoMatPrima!N11>0,(PesoMatPrima!N11*Tela!$J$7)+Acc!$AP$10+ManoDeObra!$E$11,0) -> 20.299151 | O11: =IF(PesoMatPrima!O11>0,(PesoMatPrima!O11*Tela!$J$7)+Acc!$AP$10+ManoDeObra!$E$11,0) -> 20.627918 | P11: =IF(PesoMatPrima!P11>0,(PesoMatPrima!P11*Tela!$J$7)+Acc!$AP$10+ManoDeObra!$E$11,0) -> 21.219699 | Q11: =IF(PesoMatPrima!Q11>0,(PesoMatPrima!Q11*Tela!$J$7)+Acc!$AP$10+ManoDeObra!$E$11,0) -> 21.745726
A12: 10 | B12: Calza corta | C12: =IF(PesoMatPrima!C12>0,(PesoMatPrima!C12*Tela!$J$8)+Acc!$AP$11+ManoDeObra!$C$12,0) -> 21.2488 | D12: =IF(PesoMatPrima!D12>0,(PesoMatPrima!D12*Tela!$J$8)+Acc!$AP$11+ManoDeObra!$C$12,0) -> 22.2856 | E12: =IF(PesoMatPrima!E12>0,(PesoMatPrima!E12*Tela!$J$8)+Acc!$AP$11+ManoDeObra!$C$12,0) -> 23.3224 | F12: =IF(PesoMatPrima!F12>0,(PesoMatPrima!F12*Tela!$J$8)+Acc!$AP$11+ManoDeObra!$C$12,0) -> 24.3592 | G12: =IF(PesoMatPrima!G12>0,(PesoMatPrima!G12*Tela!$J$8)+Acc!$AP$11+ManoDeObra!$C$12,0) -> 25.396 | H12: =IF(PesoMatPrima!H12>0,(PesoMatPrima!H12*Tela!$J$8)+Acc!$AP$11+ManoDeObra!$D$12,0) -> 28.4328 | I12: =IF(PesoMatPrima!I12>0,(PesoMatPrima!I12*Tela!$J$8)+Acc!$AP$11+ManoDeObra!$D$12,0) -> 29.4696 | J12: =IF(PesoMatPrima!J12>0,(PesoMatPrima!J12*Tela!$J$8)+Acc!$AP$11+ManoDeObra!$D$12,0) -> 30.5064 | K12: =IF(PesoMatPrima!K12>0,(PesoMatPrima!K12*Tela!$J$8)+Acc!$AP$11+ManoDeObra!$D$12,0) -> 0 | L12: =IF(PesoMatPrima!L12>0,(PesoMatPrima!L12*Tela!$J$8)+Acc!$AP$11+ManoDeObra!$D$12,0) -> 31.5432 | M12: =IF(PesoMatPrima!M12>0,(PesoMatPrima!M12*Tela!$J$8)+Acc!$AP$11+ManoDeObra!$D$12,0) -> 32.58 | N12: =IF(PesoMatPrima!N12>0,(PesoMatPrima!N12*Tela!$J$8)+Acc!$AP$11+ManoDeObra!$D$12,0) -> 33.876 | O12: =IF(PesoMatPrima!O12>0,(PesoMatPrima!O12*Tela!$J$8)+Acc!$AP$11+ManoDeObra!$D$12,0) -> 35.172 | ... Q12: =IF(PesoMatPrima!Q12>0,(PesoMatPrima!Q12*Tela!$J$8)+Acc!$AP$11+ManoDeObra!$D$12,0) -> 37.764
A13: 11 | B13: Calza larga | C13: =IF(PesoMatPrima!C13>0,(PesoMatPrima!C13*Tela!$J$8)+Acc!$AP$11+ManoDeObra!$C$13,0) -> 26.2664 | D13: =IF(PesoMatPrima!D13>0,(PesoMatPrima!D13*Tela!$J$8)+Acc!$AP$11+ManoDeObra!$C$13,0) -> 27.9512 | E13: =IF(PesoMatPrima!E13>0,(PesoMatPrima!E13*Tela!$J$8)+Acc!$AP$11+ManoDeObra!$C$13,0) -> 29.636 | F13: =IF(PesoMatPrima!F13>0,(PesoMatPrima!F13*Tela!$J$8)+Acc!$AP$11+ManoDeObra!$C$13,0) -> 30.932 | G13: =IF(PesoMatPrima!G13>0,(PesoMatPrima!G13*Tela!$J$8)+Acc!$AP$11+ManoDeObra!$C$13,0) -> 32.228 | H13: =IF(PesoMatPrima!H13>0,(PesoMatPrima!H13*Tela!$J$8)+Acc!$AP$11+ManoDeObra!$D$13,0) -> 43.6888 | I13: =IF(PesoMatPrima!I13>0,(PesoMatPrima!I13*Tela!$J$8)+Acc!$AP$11+ManoDeObra!$D$13,0) -> 46.54 | J13: =IF(PesoMatPrima!J13>0,(PesoMatPrima!J13*Tela!$J$8)+Acc!$AP$11+ManoDeObra!$D$13,0) -> 48.0952 | K13: =IF(PesoMatPrima!K13>0,(PesoMatPrima!K13*Tela!$J$8)+Acc!$AP$11+ManoDeObra!$D$13,0) -> 0 | L13: =IF(PesoMatPrima!L13>0,(PesoMatPrima!L13*Tela!$J$8)+Acc!$AP$11+ManoDeObra!$D$13,0) -> 49.9096 | M13: =IF(PesoMatPrima!M13>0,(PesoMatPrima!M13*Tela!$J$8)+Acc!$AP$11+ManoDeObra!$E$13,0) -> 52.428 | N13: =IF(PesoMatPrima!N13>0,(PesoMatPrima!N13*Tela!$J$8)+Acc!$AP$11+ManoDeObra!$E$13,0) -> 52.8168 | O13: =IF(PesoMatPrima!O13>0,(PesoMatPrima!O13*Tela!$J$8)+Acc!$AP$11+ManoDeObra!$E$13,0) -> 53.724 | P13: =IF(PesoMatPrima!P13>0,(PesoMatPrima!P13*Tela!$J$8)+Acc!$AP$11+ManoDeObra!$E$13,0) -> 55.668 | Q13: =IF(PesoMatPrima!Q13>0,(PesoMatPrima!Q13*Tela!$J$8)+Acc!$AP$11+ManoDeObra!$E$13,0) -> 57.3528
A14: 12 | B14: Pantalón para dama | C14: =IF(PesoMatPrima!C14>0,(PesoMatPrima!C14*Tela!$J$5)+Acc!$AP$12+ManoDeObra!$C$14,0) -> 0 | D14: =IF(PesoMatPrima!D14>0,(PesoMatPrima!D14*Tela!$J$5)+Acc!$AP$12+ManoDeObra!$C$14,0) -> 0 | E14: =IF(PesoMatPrima!E14>0,(PesoMatPrima!E14*Tela!$J$5)+Acc!$AP$12+ManoDeObra!$C$14,0) -> 0 | F14: =IF(PesoMatPrima!F14>0,(PesoMatPrima!F14*Tela!$J$5)+Acc!$AP$12+ManoDeObra!$C$14,0) -> 0 | G14: =IF(PesoMatPrima!G14>0,(PesoMatPrima!G14*Tela!$J$5)+Acc!$AP$12+ManoDeObra!$C$14,0) -> 0 | H14: =IF(PesoMatPrima!H14>0,(PesoMatPrima!H14*Tela!$J$5)+Acc!$AP$12+ManoDeObra!$D$14,0) -> 0 | I14: =IF(PesoMatPrima!I14>0,(PesoMatPrima!I14*Tela!$J$5)+Acc!$AP$12+ManoDeObra!$D$14,0) -> 0 | J14: =IF(PesoMatPrima!J14>0,(PesoMatPrima!J14*Tela!$J$5)+Acc!$AP$12+ManoDeObra!$D$14,0) -> 61.386098 | K14: =IF(PesoMatPrima!K14>0,(PesoMatPrima!K14*Tela!$J$5)+Acc!$AP$12+ManoDeObra!$D$14,0) -> 63.475854 | L14: =IF(PesoMatPrima!L14>0,(PesoMatPrima!L14*Tela!$J$5)+Acc!$AP$12+ManoDeObra!$E$14,0) -> 65.56561 | M14: =IF(PesoMatPrima!M14>0,(PesoMatPrima!M14*Tela!$J$5)+Acc!$AP$12+ManoDeObra!$E$14,0) -> 67.409512 | N14: =IF(PesoMatPrima!N14>0,(PesoMatPrima!N14*Tela!$J$5)+Acc!$AP$12+ManoDeObra!$E$14,0) -> 68.884634 | O14: =IF(PesoMatPrima!O14>0,(PesoMatPrima!O14*Tela!$J$5)+Acc!$AP$12+ManoDeObra!$E$14,0) -> 69.622195 | P14: =IF(PesoMatPrima!P14>0,(PesoMatPrima!P14*Tela!$J$5)+Acc!$AP$12+ManoDeObra!$E$14,0) -> 70.482683 | Q14: =IF(PesoMatPrima!Q14>0,(PesoMatPrima!Q14*Tela!$J$5)+Acc!$AP$12+ManoDeObra!$E$14,0) -> 71.711951
A15: 13 | B15: Blusa manga corta | C15: =IF(PesoMatPrima!C15>0,(PesoMatPrima!C15*Tela!$J$6)+Acc!$AP$13+ManoDeObra!$C$15,0) -> 43.010649 | D15: =IF(PesoMatPrima!D15>0,(PesoMatPrima!D15*Tela!$J$6)+Acc!$AP$13+ManoDeObra!$C$15,0) -> 43.966401 | E15: =IF(PesoMatPrima!E15>0,(PesoMatPrima!E15*Tela!$J$6)+Acc!$AP$13+ManoDeObra!$C$15,0) -> 44.762861 | F15: =IF(PesoMatPrima!F15>0,(PesoMatPrima!F15*Tela!$J$6)+Acc!$AP$13+ManoDeObra!$C$15,0) -> 46.99295 | G15: =IF(PesoMatPrima!G15>0,(PesoMatPrima!G15*Tela!$J$6)+Acc!$AP$13+ManoDeObra!$C$15,0) -> 48.58587 | H15: =IF(PesoMatPrima!H15>0,(PesoMatPrima!H15*Tela!$J$6)+Acc!$AP$13+ManoDeObra!$D$15,0) -> 52.700914 | I15: =IF(PesoMatPrima!I15>0,(PesoMatPrima!I15*Tela!$J$6)+Acc!$AP$13+ManoDeObra!$D$15,0) -> 53.019499 | J15: =IF(PesoMatPrima!J15>0,(PesoMatPrima!J15*Tela!$J$6)+Acc!$AP$13+ManoDeObra!$D$15,0) -> 53.815959 | K15: =IF(PesoMatPrima!K15>0,(PesoMatPrima!K15*Tela!$J$6)+Acc!$AP$13+ManoDeObra!$D$15,0) -> 54.771711 | L15: =IF(PesoMatPrima!L15>0,(PesoMatPrima!L15*Tela!$J$6)+Acc!$AP$13+ManoDeObra!$E$15,0) -> 59.090295 | M15: =IF(PesoMatPrima!M15>0,(PesoMatPrima!M15*Tela!$J$6)+Acc!$AP$13+ManoDeObra!$E$15,0) -> 59.568171 | N15: =IF(PesoMatPrima!N15>0,(PesoMatPrima!N15*Tela!$J$6)+Acc!$AP$13+ManoDeObra!$E$15,0) -> 59.886755 | O15: =IF(PesoMatPrima!O15>0,(PesoMatPrima!O15*Tela!$J$6)+Acc!$AP$13+ManoDeObra!$E$15,0) -> 61.161091 | P15: =IF(PesoMatPrima!P15>0,(PesoMatPrima!P15*Tela!$J$6)+Acc!$AP$13+ManoDeObra!$E$15,0) -> 61.957552 | Q15: =IF(PesoMatPrima!Q15>0,(PesoMatPrima!Q15*Tela!$J$6)+Acc!$AP$13+ManoDeObra!$E$15,0) -> 62.754012
A16: 14 | B16: Blusa manga larga | C16: =IF(PesoMatPrima!C16>0,(PesoMatPrima!C16*Tela!$J$6)+Acc!$AP$13+ManoDeObra!$C$15,0) -> 43.647817 | D16: =IF(PesoMatPrima!D16>0,(PesoMatPrima!D16*Tela!$J$6)+Acc!$AP$13+ManoDeObra!$C$15,0) -> 44.603569 | E16: =IF(PesoMatPrima!E16>0,(PesoMatPrima!E16*Tela!$J$6)+Acc!$AP$13+ManoDeObra!$C$15,0) -> 45.400029 | F16: =IF(PesoMatPrima!F16>0,(PesoMatPrima!F16*Tela!$J$6)+Acc!$AP$13+ManoDeObra!$C$15,0) -> 47.630118 | G16: =IF(PesoMatPrima!G16>0,(PesoMatPrima!G16*Tela!$J$6)+Acc!$AP$13+ManoDeObra!$C$15,0) -> 49.38233 | H16: =IF(PesoMatPrima!H16>0,(PesoMatPrima!H16*Tela!$J$6)+Acc!$AP$13+ManoDeObra!$D$15,0) -> 53.497375 | I16: =IF(PesoMatPrima!I16>0,(PesoMatPrima!I16*Tela!$J$6)+Acc!$AP$13+ManoDeObra!$D$15,0) -> 53.815959 | J16: =IF(PesoMatPrima!J16>0,(PesoMatPrima!J16*Tela!$J$6)+Acc!$AP$13+ManoDeObra!$D$15,0) -> 54.612419 | K16: =IF(PesoMatPrima!K16>0,(PesoMatPrima!K16*Tela!$J$6)+Acc!$AP$13+ManoDeObra!$D$15,0) -> 55.568171 | L16: =IF(PesoMatPrima!L16>0,(PesoMatPrima!L16*Tela!$J$6)+Acc!$AP$13+ManoDeObra!$E$15,0) -> 60.205339 | M16: =IF(PesoMatPrima!M16>0,(PesoMatPrima!M16*Tela!$J$6)+Acc!$AP$13+ManoDeObra!$E$15,0) -> 60.683215 | N16: =IF(PesoMatPrima!N16>0,(PesoMatPrima!N16*Tela!$J$6)+Acc!$AP$13+ManoDeObra!$E$15,0) -> 61.001799 | O16: =IF(PesoMatPrima!O16>0,(PesoMatPrima!O16*Tela!$J$6)+Acc!$AP$13+ManoDeObra!$E$15,0) -> 62.276136 | P16: =IF(PesoMatPrima!P16>0,(PesoMatPrima!P16*Tela!$J$6)+Acc!$AP$13+ManoDeObra!$E$15,0) -> 63.072596 | Q16: =IF(PesoMatPrima!Q16>0,(PesoMatPrima!Q16*Tela!$J$6)+Acc!$AP$13+ManoDeObra!$E$15,0) -> 63.869056
A17: 15 | B17: Corbata con elástico | C17: =IF(PesoMatPrima!C17>0,(PesoMatPrima!C17*Tela!$J$10)+Acc!$AP$15+ManoDeObra!$C$17,0) -> 11.185294 | D17: =IF(PesoMatPrima!D17>0,(PesoMatPrima!D17*Tela!$J$10)+Acc!$AP$15+ManoDeObra!$C$17,0) -> 0 | E17: =IF(PesoMatPrima!E17>0,(PesoMatPrima!E17*Tela!$J$10)+Acc!$AP$15+ManoDeObra!$C$17,0) -> 0 | F17: =IF(PesoMatPrima!F17>0,(PesoMatPrima!F17*Tela!$J$10)+Acc!$AP$15+ManoDeObra!$C$17,0) -> 0 | G17: =IF(PesoMatPrima!G17>0,(PesoMatPrima!G17*Tela!$J$10)+Acc!$AP$15+ManoDeObra!$C$17,0) -> 0 | H17: =IF(PesoMatPrima!H17>0,(PesoMatPrima!H17*Tela!$J$10)+Acc!$AP$15+ManoDeObra!$C$17,0) -> 0 | I17: =IF(PesoMatPrima!I17>0,(PesoMatPrima!I17*Tela!$J$10)+Acc!$AP$15+ManoDeObra!$C$17,0) -> 0 | J17: =IF(PesoMatPrima!J17>0,(PesoMatPrima!J17*Tela!$J$10)+Acc!$AP$15+ManoDeObra!$C$17,0) -> 0 | ... Q17: =IF(PesoMatPrima!Q17>0,(PesoMatPrima!Q17*Tela!$J$10)+Acc!$AP$15+ManoDeObra!$C$17,0) -> 0
